2024-06-06 14:17:05 ERROR [Errno 11] Could not exclusively lock port /dev/ttyUSB1: [Errno 11] Resource temporarily unavailable
2024-06-06 14:17:05 ERROR [Errno 11] Could not exclusively lock port /dev/ttyUSB1: [Errno 11] Resource temporarily unavailable
2024-06-06 14:17:05 ERROR [Errno 11] Could not exclusively lock port /dev/ttyUSB1: [Errno 11] Resource temporarily unavailable
2024-06-06 14:17:05 ERROR Error in get_ph: Modbus Error: [Connection] Failed to connect[ModbusSerialClient /dev/ttyUSB1:0]
Traceback (most recent call last):
  File "/home/sam/Desktop/control_loop/src/devices/ham_sensor.py", line 215, in get_ph
    return round(self.callibration_func(self.__get_raw_ph()), 3)
  File "/home/sam/Desktop/control_loop/src/devices/ham_sensor.py", line 238, in __get_raw_ph
    response = self.client.read_holding_registers(address=2089, count=10, slave=1)
  File "/home/sam/Desktop/control_loop/env/lib/python3.10/site-packages/pymodbus/client/mixin.py", line 107, in read_holding_registers
    return self.execute(
  File "/home/sam/Desktop/control_loop/env/lib/python3.10/site-packages/pymodbus/client/base.py", line 391, in execute
    raise ConnectionException(f"Failed to connect[{self!s}]")
pymodbus.exceptions.ConnectionException: Modbus Error: [Connection] Failed to connect[ModbusSerialClient /dev/ttyUSB1:0]

2024-06-06 14:17:05 ERROR [Errno 11] Could not exclusively lock port /dev/ttyUSB1: [Errno 11] Resource temporarily unavailable
2024-06-06 14:17:05 ERROR Error in get_temp: Modbus Error: [Connection] Failed to connect[ModbusSerialClient /dev/ttyUSB1:0]
Traceback (most recent call last):
  File "/home/sam/Desktop/control_loop/src/devices/ham_sensor.py", line 38, in get_temp
    res = self.client.read_holding_registers(address=2409, count=10, slave=1)
  File "/home/sam/Desktop/control_loop/env/lib/python3.10/site-packages/pymodbus/client/mixin.py", line 107, in read_holding_registers
    return self.execute(
  File "/home/sam/Desktop/control_loop/env/lib/python3.10/site-packages/pymodbus/client/base.py", line 391, in execute
    raise ConnectionException(f"Failed to connect[{self!s}]")
pymodbus.exceptions.ConnectionException: Modbus Error: [Connection] Failed to connect[ModbusSerialClient /dev/ttyUSB1:0]

2024-06-06 14:17:05 ERROR [Errno 11] Could not exclusively lock port /dev/ttyUSB1: [Errno 11] Resource temporarily unavailable
2024-06-06 14:17:05 ERROR Error in get_ph: Modbus Error: [Connection] Failed to connect[ModbusSerialClient /dev/ttyUSB1:0]
Traceback (most recent call last):
  File "/home/sam/Desktop/control_loop/src/devices/ham_sensor.py", line 215, in get_ph
    return round(self.callibration_func(self.__get_raw_ph()), 3)
  File "/home/sam/Desktop/control_loop/src/devices/ham_sensor.py", line 238, in __get_raw_ph
    response = self.client.read_holding_registers(address=2089, count=10, slave=1)
  File "/home/sam/Desktop/control_loop/env/lib/python3.10/site-packages/pymodbus/client/mixin.py", line 107, in read_holding_registers
    return self.execute(
  File "/home/sam/Desktop/control_loop/env/lib/python3.10/site-packages/pymodbus/client/base.py", line 391, in execute
    raise ConnectionException(f"Failed to connect[{self!s}]")
pymodbus.exceptions.ConnectionException: Modbus Error: [Connection] Failed to connect[ModbusSerialClient /dev/ttyUSB1:0]

2024-06-06 14:17:05 ERROR [Errno 11] Could not exclusively lock port /dev/ttyUSB1: [Errno 11] Resource temporarily unavailable
2024-06-06 14:17:05 ERROR Error in get_temp: Modbus Error: [Connection] Failed to connect[ModbusSerialClient /dev/ttyUSB1:0]
Traceback (most recent call last):
  File "/home/sam/Desktop/control_loop/src/devices/ham_sensor.py", line 38, in get_temp
    res = self.client.read_holding_registers(address=2409, count=10, slave=1)
  File "/home/sam/Desktop/control_loop/env/lib/python3.10/site-packages/pymodbus/client/mixin.py", line 107, in read_holding_registers
    return self.execute(
  File "/home/sam/Desktop/control_loop/env/lib/python3.10/site-packages/pymodbus/client/base.py", line 391, in execute
    raise ConnectionException(f"Failed to connect[{self!s}]")
pymodbus.exceptions.ConnectionException: Modbus Error: [Connection] Failed to connect[ModbusSerialClient /dev/ttyUSB1:0]

