2024-07-05 12:16:21 - ERROR - Error in handle_client
Unexpected error: no close frame received or sent
Traceback (most recent call last):
  File "/home/sam/Desktop/control_loop/env/lib/python3.10/site-packages/websockets/legacy/protocol.py", line 963, in transfer_data
    message = await self.read_message()
  File "/home/sam/Desktop/control_loop/env/lib/python3.10/site-packages/websockets/legacy/protocol.py", line 1033, in read_message
    frame = await self.read_data_frame(max_size=self.max_size)
  File "/home/sam/Desktop/control_loop/env/lib/python3.10/site-packages/websockets/legacy/protocol.py", line 1108, in read_data_frame
    frame = await self.read_frame(max_size)
  File "/home/sam/Desktop/control_loop/env/lib/python3.10/site-packages/websockets/legacy/protocol.py", line 1165, in read_frame
    frame = await Frame.read(
  File "/home/sam/Desktop/control_loop/env/lib/python3.10/site-packages/websockets/legacy/framing.py", line 68, in read
    data = await reader(2)
  File "/usr/lib/python3.10/asyncio/streams.py", line 706, in readexactly
    raise exceptions.IncompleteReadError(incomplete, n)
asyncio.exceptions.IncompleteReadError: 0 bytes read on a total of 2 expected bytes

The above exception was the direct cause of the following exception:

Traceback (most recent call last):
  File "/home/sam/Desktop/control_loop/webapp/backend/api_server.py", line 53, in handle_client
    message = await asyncio.wait_for(websocket.recv(), timeout=60)
  File "/usr/lib/python3.10/asyncio/tasks.py", line 445, in wait_for
    return fut.result()
  File "/home/sam/Desktop/control_loop/env/lib/python3.10/site-packages/websockets/legacy/protocol.py", line 568, in recv
    await self.ensure_open()
  File "/home/sam/Desktop/control_loop/env/lib/python3.10/site-packages/websockets/legacy/protocol.py", line 939, in ensure_open
    raise self.connection_closed_exc()
websockets.exceptions.ConnectionClosedError: no close frame received or sent

2024-07-05 12:16:30 - ERROR - Error in get_controller: 
 Input: fermentation_loop, 
 'FermentationController' object has no attribute 'device_manager'
Traceback (most recent call last):
  File "/home/sam/Desktop/control_loop/webapp/backend/manager_server.py", line 270, in get_controller
    controller, device_manager = c.create_controller(loop_id)
  File "/home/sam/Desktop/control_loop/webapp/backend/../../src/controllers_mqtt.py", line 43, in create_controller
    return controller, controller.device_manager
AttributeError: 'FermentationController' object has no attribute 'device_manager'

2024-07-05 12:16:30 - ERROR - Error in collection: 
Input: start_collection, 
argument of type 'NoneType' is not iterable
Traceback (most recent call last):
  File "/home/sam/Desktop/control_loop/webapp/backend/manager_server.py", line 71, in collection
    if "collection_task" not in controller_info: # if data collection is not already happening then start it
TypeError: argument of type 'NoneType' is not iterable

2024-07-05 12:20:20 - ERROR - Error in handle_client
Unexpected error: no close frame received or sent
Traceback (most recent call last):
  File "/home/sam/Desktop/control_loop/env/lib/python3.10/site-packages/websockets/legacy/protocol.py", line 963, in transfer_data
    message = await self.read_message()
  File "/home/sam/Desktop/control_loop/env/lib/python3.10/site-packages/websockets/legacy/protocol.py", line 1033, in read_message
    frame = await self.read_data_frame(max_size=self.max_size)
  File "/home/sam/Desktop/control_loop/env/lib/python3.10/site-packages/websockets/legacy/protocol.py", line 1108, in read_data_frame
    frame = await self.read_frame(max_size)
  File "/home/sam/Desktop/control_loop/env/lib/python3.10/site-packages/websockets/legacy/protocol.py", line 1165, in read_frame
    frame = await Frame.read(
  File "/home/sam/Desktop/control_loop/env/lib/python3.10/site-packages/websockets/legacy/framing.py", line 68, in read
    data = await reader(2)
  File "/usr/lib/python3.10/asyncio/streams.py", line 706, in readexactly
    raise exceptions.IncompleteReadError(incomplete, n)
asyncio.exceptions.IncompleteReadError: 0 bytes read on a total of 2 expected bytes

The above exception was the direct cause of the following exception:

Traceback (most recent call last):
  File "/home/sam/Desktop/control_loop/webapp/backend/api_server.py", line 53, in handle_client
    message = await asyncio.wait_for(websocket.recv(), timeout=60)
  File "/usr/lib/python3.10/asyncio/tasks.py", line 445, in wait_for
    return fut.result()
  File "/home/sam/Desktop/control_loop/env/lib/python3.10/site-packages/websockets/legacy/protocol.py", line 568, in recv
    await self.ensure_open()
  File "/home/sam/Desktop/control_loop/env/lib/python3.10/site-packages/websockets/legacy/protocol.py", line 939, in ensure_open
    raise self.connection_closed_exc()
websockets.exceptions.ConnectionClosedError: no close frame received or sent

2024-07-05 12:21:10 - ERROR - Error in handle_client
Unexpected error: received 1001 (going away); then sent 1001 (going away)
Traceback (most recent call last):
  File "/home/sam/Desktop/control_loop/webapp/backend/api_server.py", line 53, in handle_client
    message = await asyncio.wait_for(websocket.recv(), timeout=60)
  File "/usr/lib/python3.10/asyncio/tasks.py", line 445, in wait_for
    return fut.result()
  File "/home/sam/Desktop/control_loop/env/lib/python3.10/site-packages/websockets/legacy/protocol.py", line 568, in recv
    await self.ensure_open()
  File "/home/sam/Desktop/control_loop/env/lib/python3.10/site-packages/websockets/legacy/protocol.py", line 948, in ensure_open
    raise self.connection_closed_exc()
websockets.exceptions.ConnectionClosedOK: received 1001 (going away); then sent 1001 (going away)

2024-07-05 12:21:10 - ERROR - Error in handle_client
Unexpected error: received 1001 (going away); then sent 1001 (going away)
Traceback (most recent call last):
  File "/home/sam/Desktop/control_loop/webapp/backend/api_server.py", line 53, in handle_client
    message = await asyncio.wait_for(websocket.recv(), timeout=60)
  File "/usr/lib/python3.10/asyncio/tasks.py", line 445, in wait_for
    return fut.result()
  File "/home/sam/Desktop/control_loop/env/lib/python3.10/site-packages/websockets/legacy/protocol.py", line 568, in recv
    await self.ensure_open()
  File "/home/sam/Desktop/control_loop/env/lib/python3.10/site-packages/websockets/legacy/protocol.py", line 948, in ensure_open
    raise self.connection_closed_exc()
websockets.exceptions.ConnectionClosedOK: received 1001 (going away); then sent 1001 (going away)

2024-07-05 12:21:11 - ERROR - Backup Server Starting
2024-07-05 12:21:11 - ERROR - Error in send_status_update: 
 Input: {'type': 'status', 'loopID': 'fermentation_loop', 'control_loop_status': 'control_off', 'data_collection_status': 'data_collection_off', 'feed_pump_status': '0', 'base_pump_status': '2', 'acid_pump_status': '14', 'antifoam_pump_status': '4'}, 
 received 1001 (going away); then sent 1001 (going away)
Traceback (most recent call last):
  File "/home/sam/Desktop/control_loop/webapp/backend/manager_server.py", line 250, in send_status_update
    await websocket.send(json.dumps({"type": "status", **status}))
  File "/home/sam/Desktop/control_loop/env/lib/python3.10/site-packages/websockets/legacy/protocol.py", line 635, in send
    await self.ensure_open()
  File "/home/sam/Desktop/control_loop/env/lib/python3.10/site-packages/websockets/legacy/protocol.py", line 939, in ensure_open
    raise self.connection_closed_exc()
websockets.exceptions.ConnectionClosedOK: received 1001 (going away); then sent 1001 (going away)

2024-07-05 12:21:41 - ERROR - Backup Server Started
2024-07-05 12:21:41 - ERROR - Error in handle_client
Unexpected error: no close frame received or sent
Traceback (most recent call last):
  File "/home/sam/Desktop/control_loop/env/lib/python3.10/site-packages/websockets/legacy/protocol.py", line 963, in transfer_data
    message = await self.read_message()
  File "/home/sam/Desktop/control_loop/env/lib/python3.10/site-packages/websockets/legacy/protocol.py", line 1033, in read_message
    frame = await self.read_data_frame(max_size=self.max_size)
  File "/home/sam/Desktop/control_loop/env/lib/python3.10/site-packages/websockets/legacy/protocol.py", line 1108, in read_data_frame
    frame = await self.read_frame(max_size)
  File "/home/sam/Desktop/control_loop/env/lib/python3.10/site-packages/websockets/legacy/protocol.py", line 1165, in read_frame
    frame = await Frame.read(
  File "/home/sam/Desktop/control_loop/env/lib/python3.10/site-packages/websockets/legacy/framing.py", line 68, in read
    data = await reader(2)
  File "/usr/lib/python3.10/asyncio/streams.py", line 706, in readexactly
    raise exceptions.IncompleteReadError(incomplete, n)
asyncio.exceptions.IncompleteReadError: 0 bytes read on a total of 2 expected bytes

The above exception was the direct cause of the following exception:

Traceback (most recent call last):
  File "/home/sam/Desktop/control_loop/webapp/backend/api_server.py", line 53, in handle_client
    message = await asyncio.wait_for(websocket.recv(), timeout=60)
  File "/usr/lib/python3.10/asyncio/tasks.py", line 445, in wait_for
    return fut.result()
  File "/home/sam/Desktop/control_loop/env/lib/python3.10/site-packages/websockets/legacy/protocol.py", line 568, in recv
    await self.ensure_open()
  File "/home/sam/Desktop/control_loop/env/lib/python3.10/site-packages/websockets/legacy/protocol.py", line 939, in ensure_open
    raise self.connection_closed_exc()
websockets.exceptions.ConnectionClosedError: no close frame received or sent

2024-07-05 12:21:41 - ERROR - Error in handle_client
Unexpected error: no close frame received or sent
Traceback (most recent call last):
  File "/home/sam/Desktop/control_loop/env/lib/python3.10/site-packages/websockets/legacy/protocol.py", line 963, in transfer_data
    message = await self.read_message()
  File "/home/sam/Desktop/control_loop/env/lib/python3.10/site-packages/websockets/legacy/protocol.py", line 1033, in read_message
    frame = await self.read_data_frame(max_size=self.max_size)
  File "/home/sam/Desktop/control_loop/env/lib/python3.10/site-packages/websockets/legacy/protocol.py", line 1108, in read_data_frame
    frame = await self.read_frame(max_size)
  File "/home/sam/Desktop/control_loop/env/lib/python3.10/site-packages/websockets/legacy/protocol.py", line 1165, in read_frame
    frame = await Frame.read(
  File "/home/sam/Desktop/control_loop/env/lib/python3.10/site-packages/websockets/legacy/framing.py", line 68, in read
    data = await reader(2)
  File "/usr/lib/python3.10/asyncio/streams.py", line 706, in readexactly
    raise exceptions.IncompleteReadError(incomplete, n)
asyncio.exceptions.IncompleteReadError: 0 bytes read on a total of 2 expected bytes

The above exception was the direct cause of the following exception:

Traceback (most recent call last):
  File "/home/sam/Desktop/control_loop/webapp/backend/api_server.py", line 53, in handle_client
    message = await asyncio.wait_for(websocket.recv(), timeout=60)
  File "/usr/lib/python3.10/asyncio/tasks.py", line 445, in wait_for
    return fut.result()
  File "/home/sam/Desktop/control_loop/env/lib/python3.10/site-packages/websockets/legacy/protocol.py", line 568, in recv
    await self.ensure_open()
  File "/home/sam/Desktop/control_loop/env/lib/python3.10/site-packages/websockets/legacy/protocol.py", line 939, in ensure_open
    raise self.connection_closed_exc()
websockets.exceptions.ConnectionClosedError: no close frame received or sent

2024-07-05 12:21:41 - ERROR - Error in send_notification: Bad message: must be 0-1024 characters, was 1923
Traceback (most recent call last):
  File "/home/sam/Desktop/control_loop/env/lib/python3.10/site-packages/websockets/legacy/protocol.py", line 963, in transfer_data
    message = await self.read_message()
  File "/home/sam/Desktop/control_loop/env/lib/python3.10/site-packages/websockets/legacy/protocol.py", line 1033, in read_message
    frame = await self.read_data_frame(max_size=self.max_size)
  File "/home/sam/Desktop/control_loop/env/lib/python3.10/site-packages/websockets/legacy/protocol.py", line 1108, in read_data_frame
    frame = await self.read_frame(max_size)
  File "/home/sam/Desktop/control_loop/env/lib/python3.10/site-packages/websockets/legacy/protocol.py", line 1165, in read_frame
    frame = await Frame.read(
  File "/home/sam/Desktop/control_loop/env/lib/python3.10/site-packages/websockets/legacy/framing.py", line 68, in read
    data = await reader(2)
  File "/usr/lib/python3.10/asyncio/streams.py", line 706, in readexactly
    raise exceptions.IncompleteReadError(incomplete, n)
asyncio.exceptions.IncompleteReadError: 0 bytes read on a total of 2 expected bytes

The above exception was the direct cause of the following exception:

Traceback (most recent call last):
  File "/home/sam/Desktop/control_loop/webapp/backend/api_server.py", line 53, in handle_client
    message = await asyncio.wait_for(websocket.recv(), timeout=60)
  File "/usr/lib/python3.10/asyncio/tasks.py", line 445, in wait_for
    return fut.result()
  File "/home/sam/Desktop/control_loop/env/lib/python3.10/site-packages/websockets/legacy/protocol.py", line 568, in recv
    await self.ensure_open()
  File "/home/sam/Desktop/control_loop/env/lib/python3.10/site-packages/websockets/legacy/protocol.py", line 939, in ensure_open
    raise self.connection_closed_exc()
websockets.exceptions.ConnectionClosedError: no close frame received or sent

During handling of the above exception, another exception occurred:

Traceback (most recent call last):
  File "/home/sam/Desktop/control_loop/webapp/backend/../../src/resources/error_notification.py", line 18, in send_notification
    message = user.send_message(f"{message}", priority=priority)
  File "/home/sam/Desktop/control_loop/env/lib/python3.10/site-packages/chump/__init__.py", line 563, in send_message
    message = self.create_message(
  File "/home/sam/Desktop/control_loop/env/lib/python3.10/site-packages/chump/__init__.py", line 549, in create_message
    return message_class(self, **kwargs)
  File "/home/sam/Desktop/control_loop/env/lib/python3.10/site-packages/chump/__init__.py", line 781, in __init__
    super(EmergencyMessage, self).__init__(
  File "/home/sam/Desktop/control_loop/env/lib/python3.10/site-packages/chump/__init__.py", line 590, in __init__
    self.message = message
  File "/home/sam/Desktop/control_loop/env/lib/python3.10/site-packages/chump/__init__.py", line 825, in __setattr__
    super(EmergencyMessage, self).__setattr__(name, value)
  File "/home/sam/Desktop/control_loop/env/lib/python3.10/site-packages/chump/__init__.py", line 645, in __setattr__
    raise ValueError('Bad message: must be 0-1024 characters, was {length}'.format(length=len(value)))
ValueError: Bad message: must be 0-1024 characters, was 1923

2024-07-05 12:21:41 - ERROR - Backup Server Starting
2024-07-05 12:21:41 - ERROR - Error in handle_client
Unexpected error: no close frame received or sent
Traceback (most recent call last):
  File "/home/sam/Desktop/control_loop/env/lib/python3.10/site-packages/websockets/legacy/protocol.py", line 963, in transfer_data
    message = await self.read_message()
  File "/home/sam/Desktop/control_loop/env/lib/python3.10/site-packages/websockets/legacy/protocol.py", line 1033, in read_message
    frame = await self.read_data_frame(max_size=self.max_size)
  File "/home/sam/Desktop/control_loop/env/lib/python3.10/site-packages/websockets/legacy/protocol.py", line 1108, in read_data_frame
    frame = await self.read_frame(max_size)
  File "/home/sam/Desktop/control_loop/env/lib/python3.10/site-packages/websockets/legacy/protocol.py", line 1165, in read_frame
    frame = await Frame.read(
  File "/home/sam/Desktop/control_loop/env/lib/python3.10/site-packages/websockets/legacy/framing.py", line 68, in read
    data = await reader(2)
  File "/usr/lib/python3.10/asyncio/streams.py", line 706, in readexactly
    raise exceptions.IncompleteReadError(incomplete, n)
asyncio.exceptions.IncompleteReadError: 0 bytes read on a total of 2 expected bytes

The above exception was the direct cause of the following exception:

Traceback (most recent call last):
  File "/home/sam/Desktop/control_loop/webapp/backend/api_server.py", line 53, in handle_client
    message = await asyncio.wait_for(websocket.recv(), timeout=60)
  File "/usr/lib/python3.10/asyncio/tasks.py", line 445, in wait_for
    return fut.result()
  File "/home/sam/Desktop/control_loop/env/lib/python3.10/site-packages/websockets/legacy/protocol.py", line 568, in recv
    await self.ensure_open()
  File "/home/sam/Desktop/control_loop/env/lib/python3.10/site-packages/websockets/legacy/protocol.py", line 939, in ensure_open
    raise self.connection_closed_exc()
websockets.exceptions.ConnectionClosedError: no close frame received or sent

2024-07-05 12:21:41 - ERROR - Error in handle_client
Unexpected error: no close frame received or sent
Traceback (most recent call last):
  File "/home/sam/Desktop/control_loop/env/lib/python3.10/site-packages/websockets/legacy/protocol.py", line 963, in transfer_data
    message = await self.read_message()
  File "/home/sam/Desktop/control_loop/env/lib/python3.10/site-packages/websockets/legacy/protocol.py", line 1033, in read_message
    frame = await self.read_data_frame(max_size=self.max_size)
  File "/home/sam/Desktop/control_loop/env/lib/python3.10/site-packages/websockets/legacy/protocol.py", line 1108, in read_data_frame
    frame = await self.read_frame(max_size)
  File "/home/sam/Desktop/control_loop/env/lib/python3.10/site-packages/websockets/legacy/protocol.py", line 1165, in read_frame
    frame = await Frame.read(
  File "/home/sam/Desktop/control_loop/env/lib/python3.10/site-packages/websockets/legacy/framing.py", line 68, in read
    data = await reader(2)
  File "/usr/lib/python3.10/asyncio/streams.py", line 706, in readexactly
    raise exceptions.IncompleteReadError(incomplete, n)
asyncio.exceptions.IncompleteReadError: 0 bytes read on a total of 2 expected bytes

The above exception was the direct cause of the following exception:

Traceback (most recent call last):
  File "/home/sam/Desktop/control_loop/webapp/backend/api_server.py", line 53, in handle_client
    message = await asyncio.wait_for(websocket.recv(), timeout=60)
  File "/usr/lib/python3.10/asyncio/tasks.py", line 445, in wait_for
    return fut.result()
  File "/home/sam/Desktop/control_loop/env/lib/python3.10/site-packages/websockets/legacy/protocol.py", line 568, in recv
    await self.ensure_open()
  File "/home/sam/Desktop/control_loop/env/lib/python3.10/site-packages/websockets/legacy/protocol.py", line 939, in ensure_open
    raise self.connection_closed_exc()
websockets.exceptions.ConnectionClosedError: no close frame received or sent

2024-07-05 12:21:41 - ERROR - Error in send_notification: Bad message: must be 0-1024 characters, was 1923
Traceback (most recent call last):
  File "/home/sam/Desktop/control_loop/env/lib/python3.10/site-packages/websockets/legacy/protocol.py", line 963, in transfer_data
    message = await self.read_message()
  File "/home/sam/Desktop/control_loop/env/lib/python3.10/site-packages/websockets/legacy/protocol.py", line 1033, in read_message
    frame = await self.read_data_frame(max_size=self.max_size)
  File "/home/sam/Desktop/control_loop/env/lib/python3.10/site-packages/websockets/legacy/protocol.py", line 1108, in read_data_frame
    frame = await self.read_frame(max_size)
  File "/home/sam/Desktop/control_loop/env/lib/python3.10/site-packages/websockets/legacy/protocol.py", line 1165, in read_frame
    frame = await Frame.read(
  File "/home/sam/Desktop/control_loop/env/lib/python3.10/site-packages/websockets/legacy/framing.py", line 68, in read
    data = await reader(2)
  File "/usr/lib/python3.10/asyncio/streams.py", line 706, in readexactly
    raise exceptions.IncompleteReadError(incomplete, n)
asyncio.exceptions.IncompleteReadError: 0 bytes read on a total of 2 expected bytes

The above exception was the direct cause of the following exception:

Traceback (most recent call last):
  File "/home/sam/Desktop/control_loop/webapp/backend/api_server.py", line 53, in handle_client
    message = await asyncio.wait_for(websocket.recv(), timeout=60)
  File "/usr/lib/python3.10/asyncio/tasks.py", line 445, in wait_for
    return fut.result()
  File "/home/sam/Desktop/control_loop/env/lib/python3.10/site-packages/websockets/legacy/protocol.py", line 568, in recv
    await self.ensure_open()
  File "/home/sam/Desktop/control_loop/env/lib/python3.10/site-packages/websockets/legacy/protocol.py", line 939, in ensure_open
    raise self.connection_closed_exc()
websockets.exceptions.ConnectionClosedError: no close frame received or sent

During handling of the above exception, another exception occurred:

Traceback (most recent call last):
  File "/home/sam/Desktop/control_loop/webapp/backend/../../src/resources/error_notification.py", line 18, in send_notification
    message = user.send_message(f"{message}", priority=priority)
  File "/home/sam/Desktop/control_loop/env/lib/python3.10/site-packages/chump/__init__.py", line 563, in send_message
    message = self.create_message(
  File "/home/sam/Desktop/control_loop/env/lib/python3.10/site-packages/chump/__init__.py", line 549, in create_message
    return message_class(self, **kwargs)
  File "/home/sam/Desktop/control_loop/env/lib/python3.10/site-packages/chump/__init__.py", line 781, in __init__
    super(EmergencyMessage, self).__init__(
  File "/home/sam/Desktop/control_loop/env/lib/python3.10/site-packages/chump/__init__.py", line 590, in __init__
    self.message = message
  File "/home/sam/Desktop/control_loop/env/lib/python3.10/site-packages/chump/__init__.py", line 825, in __setattr__
    super(EmergencyMessage, self).__setattr__(name, value)
  File "/home/sam/Desktop/control_loop/env/lib/python3.10/site-packages/chump/__init__.py", line 645, in __setattr__
    raise ValueError('Bad message: must be 0-1024 characters, was {length}'.format(length=len(value)))
ValueError: Bad message: must be 0-1024 characters, was 1923

2024-07-05 12:21:41 - ERROR - Backup Server Starting
2024-07-05 12:22:37 - ERROR - Error in handle_client
Unexpected error: no close frame received or sent
Traceback (most recent call last):
  File "/home/sam/Desktop/control_loop/env/lib/python3.10/site-packages/websockets/legacy/protocol.py", line 963, in transfer_data
    message = await self.read_message()
  File "/home/sam/Desktop/control_loop/env/lib/python3.10/site-packages/websockets/legacy/protocol.py", line 1033, in read_message
    frame = await self.read_data_frame(max_size=self.max_size)
  File "/home/sam/Desktop/control_loop/env/lib/python3.10/site-packages/websockets/legacy/protocol.py", line 1108, in read_data_frame
    frame = await self.read_frame(max_size)
  File "/home/sam/Desktop/control_loop/env/lib/python3.10/site-packages/websockets/legacy/protocol.py", line 1165, in read_frame
    frame = await Frame.read(
  File "/home/sam/Desktop/control_loop/env/lib/python3.10/site-packages/websockets/legacy/framing.py", line 68, in read
    data = await reader(2)
  File "/usr/lib/python3.10/asyncio/streams.py", line 706, in readexactly
    raise exceptions.IncompleteReadError(incomplete, n)
asyncio.exceptions.IncompleteReadError: 0 bytes read on a total of 2 expected bytes

The above exception was the direct cause of the following exception:

Traceback (most recent call last):
  File "/home/sam/Desktop/control_loop/webapp/backend/api_server.py", line 53, in handle_client
    message = await asyncio.wait_for(websocket.recv(), timeout=60)
  File "/usr/lib/python3.10/asyncio/tasks.py", line 445, in wait_for
    return fut.result()
  File "/home/sam/Desktop/control_loop/env/lib/python3.10/site-packages/websockets/legacy/protocol.py", line 568, in recv
    await self.ensure_open()
  File "/home/sam/Desktop/control_loop/env/lib/python3.10/site-packages/websockets/legacy/protocol.py", line 939, in ensure_open
    raise self.connection_closed_exc()
websockets.exceptions.ConnectionClosedError: no close frame received or sent

2024-07-05 12:24:44 - ERROR - Error in handle_client
Unexpected error: no close frame received or sent
Traceback (most recent call last):
  File "/home/sam/Desktop/control_loop/env/lib/python3.10/site-packages/websockets/legacy/protocol.py", line 963, in transfer_data
    message = await self.read_message()
  File "/home/sam/Desktop/control_loop/env/lib/python3.10/site-packages/websockets/legacy/protocol.py", line 1033, in read_message
    frame = await self.read_data_frame(max_size=self.max_size)
  File "/home/sam/Desktop/control_loop/env/lib/python3.10/site-packages/websockets/legacy/protocol.py", line 1108, in read_data_frame
    frame = await self.read_frame(max_size)
  File "/home/sam/Desktop/control_loop/env/lib/python3.10/site-packages/websockets/legacy/protocol.py", line 1165, in read_frame
    frame = await Frame.read(
  File "/home/sam/Desktop/control_loop/env/lib/python3.10/site-packages/websockets/legacy/framing.py", line 68, in read
    data = await reader(2)
  File "/usr/lib/python3.10/asyncio/streams.py", line 706, in readexactly
    raise exceptions.IncompleteReadError(incomplete, n)
asyncio.exceptions.IncompleteReadError: 0 bytes read on a total of 2 expected bytes

The above exception was the direct cause of the following exception:

Traceback (most recent call last):
  File "/home/sam/Desktop/control_loop/webapp/backend/api_server.py", line 53, in handle_client
    message = await asyncio.wait_for(websocket.recv(), timeout=60)
  File "/usr/lib/python3.10/asyncio/tasks.py", line 445, in wait_for
    return fut.result()
  File "/home/sam/Desktop/control_loop/env/lib/python3.10/site-packages/websockets/legacy/protocol.py", line 568, in recv
    await self.ensure_open()
  File "/home/sam/Desktop/control_loop/env/lib/python3.10/site-packages/websockets/legacy/protocol.py", line 939, in ensure_open
    raise self.connection_closed_exc()
websockets.exceptions.ConnectionClosedError: no close frame received or sent

2024-07-05 12:25:48 - ERROR - Error in handle_client
Unexpected error: no close frame received or sent
Traceback (most recent call last):
  File "/home/sam/Desktop/control_loop/env/lib/python3.10/site-packages/websockets/legacy/protocol.py", line 963, in transfer_data
    message = await self.read_message()
  File "/home/sam/Desktop/control_loop/env/lib/python3.10/site-packages/websockets/legacy/protocol.py", line 1033, in read_message
    frame = await self.read_data_frame(max_size=self.max_size)
  File "/home/sam/Desktop/control_loop/env/lib/python3.10/site-packages/websockets/legacy/protocol.py", line 1108, in read_data_frame
    frame = await self.read_frame(max_size)
  File "/home/sam/Desktop/control_loop/env/lib/python3.10/site-packages/websockets/legacy/protocol.py", line 1165, in read_frame
    frame = await Frame.read(
  File "/home/sam/Desktop/control_loop/env/lib/python3.10/site-packages/websockets/legacy/framing.py", line 68, in read
    data = await reader(2)
  File "/usr/lib/python3.10/asyncio/streams.py", line 706, in readexactly
    raise exceptions.IncompleteReadError(incomplete, n)
asyncio.exceptions.IncompleteReadError: 0 bytes read on a total of 2 expected bytes

The above exception was the direct cause of the following exception:

Traceback (most recent call last):
  File "/home/sam/Desktop/control_loop/webapp/backend/api_server.py", line 53, in handle_client
    message = await asyncio.wait_for(websocket.recv(), timeout=60)
  File "/usr/lib/python3.10/asyncio/tasks.py", line 445, in wait_for
    return fut.result()
  File "/home/sam/Desktop/control_loop/env/lib/python3.10/site-packages/websockets/legacy/protocol.py", line 568, in recv
    await self.ensure_open()
  File "/home/sam/Desktop/control_loop/env/lib/python3.10/site-packages/websockets/legacy/protocol.py", line 939, in ensure_open
    raise self.connection_closed_exc()
websockets.exceptions.ConnectionClosedError: no close frame received or sent

2024-07-05 12:27:16 - ERROR - Error in handle_client
Unexpected error: no close frame received or sent
Traceback (most recent call last):
  File "/home/sam/Desktop/control_loop/env/lib/python3.10/site-packages/websockets/legacy/protocol.py", line 963, in transfer_data
    message = await self.read_message()
  File "/home/sam/Desktop/control_loop/env/lib/python3.10/site-packages/websockets/legacy/protocol.py", line 1033, in read_message
    frame = await self.read_data_frame(max_size=self.max_size)
  File "/home/sam/Desktop/control_loop/env/lib/python3.10/site-packages/websockets/legacy/protocol.py", line 1108, in read_data_frame
    frame = await self.read_frame(max_size)
  File "/home/sam/Desktop/control_loop/env/lib/python3.10/site-packages/websockets/legacy/protocol.py", line 1165, in read_frame
    frame = await Frame.read(
  File "/home/sam/Desktop/control_loop/env/lib/python3.10/site-packages/websockets/legacy/framing.py", line 68, in read
    data = await reader(2)
  File "/usr/lib/python3.10/asyncio/streams.py", line 706, in readexactly
    raise exceptions.IncompleteReadError(incomplete, n)
asyncio.exceptions.IncompleteReadError: 0 bytes read on a total of 2 expected bytes

The above exception was the direct cause of the following exception:

Traceback (most recent call last):
  File "/home/sam/Desktop/control_loop/webapp/backend/api_server.py", line 53, in handle_client
    message = await asyncio.wait_for(websocket.recv(), timeout=60)
  File "/usr/lib/python3.10/asyncio/tasks.py", line 445, in wait_for
    return fut.result()
  File "/home/sam/Desktop/control_loop/env/lib/python3.10/site-packages/websockets/legacy/protocol.py", line 568, in recv
    await self.ensure_open()
  File "/home/sam/Desktop/control_loop/env/lib/python3.10/site-packages/websockets/legacy/protocol.py", line 939, in ensure_open
    raise self.connection_closed_exc()
websockets.exceptions.ConnectionClosedError: no close frame received or sent

