2024-07-10 11:20:07 - ERROR - Error in handle_client
Unexpected error: no close frame received or sent
Traceback (most recent call last):
  File "/home/sam/Desktop/control_loop/env/lib/python3.10/site-packages/websockets/legacy/protocol.py", line 963, in transfer_data
    message = await self.read_message()
  File "/home/sam/Desktop/control_loop/env/lib/python3.10/site-packages/websockets/legacy/protocol.py", line 1033, in read_message
    frame = await self.read_data_frame(max_size=self.max_size)
  File "/home/sam/Desktop/control_loop/env/lib/python3.10/site-packages/websockets/legacy/protocol.py", line 1108, in read_data_frame
    frame = await self.read_frame(max_size)
  File "/home/sam/Desktop/control_loop/env/lib/python3.10/site-packages/websockets/legacy/protocol.py", line 1165, in read_frame
    frame = await Frame.read(
  File "/home/sam/Desktop/control_loop/env/lib/python3.10/site-packages/websockets/legacy/framing.py", line 68, in read
    data = await reader(2)
  File "/usr/lib/python3.10/asyncio/streams.py", line 706, in readexactly
    raise exceptions.IncompleteReadError(incomplete, n)
asyncio.exceptions.IncompleteReadError: 0 bytes read on a total of 2 expected bytes

The above exception was the direct cause of the following exception:

Traceback (most recent call last):
  File "/home/sam/Desktop/control_loop/webapp/backend/api_server.py", line 53, in handle_client
    message = await asyncio.wait_for(websocket.recv(), timeout=60)
  File "/usr/lib/python3.10/asyncio/tasks.py", line 445, in wait_for
    return fut.result()
  File "/home/sam/Desktop/control_loop/env/lib/python3.10/site-packages/websockets/legacy/protocol.py", line 568, in recv
    await self.ensure_open()
  File "/home/sam/Desktop/control_loop/env/lib/python3.10/site-packages/websockets/legacy/protocol.py", line 939, in ensure_open
    raise self.connection_closed_exc()
websockets.exceptions.ConnectionClosedError: no close frame received or sent

2024-07-10 11:22:11 - ERROR - Error in handle_client
Unexpected error: no close frame received or sent
Traceback (most recent call last):
  File "/home/sam/Desktop/control_loop/env/lib/python3.10/site-packages/websockets/legacy/protocol.py", line 963, in transfer_data
    message = await self.read_message()
  File "/home/sam/Desktop/control_loop/env/lib/python3.10/site-packages/websockets/legacy/protocol.py", line 1033, in read_message
    frame = await self.read_data_frame(max_size=self.max_size)
  File "/home/sam/Desktop/control_loop/env/lib/python3.10/site-packages/websockets/legacy/protocol.py", line 1108, in read_data_frame
    frame = await self.read_frame(max_size)
  File "/home/sam/Desktop/control_loop/env/lib/python3.10/site-packages/websockets/legacy/protocol.py", line 1165, in read_frame
    frame = await Frame.read(
  File "/home/sam/Desktop/control_loop/env/lib/python3.10/site-packages/websockets/legacy/framing.py", line 68, in read
    data = await reader(2)
  File "/usr/lib/python3.10/asyncio/streams.py", line 706, in readexactly
    raise exceptions.IncompleteReadError(incomplete, n)
asyncio.exceptions.IncompleteReadError: 0 bytes read on a total of 2 expected bytes

The above exception was the direct cause of the following exception:

Traceback (most recent call last):
  File "/home/sam/Desktop/control_loop/webapp/backend/api_server.py", line 53, in handle_client
    message = await asyncio.wait_for(websocket.recv(), timeout=60)
  File "/usr/lib/python3.10/asyncio/tasks.py", line 445, in wait_for
    return fut.result()
  File "/home/sam/Desktop/control_loop/env/lib/python3.10/site-packages/websockets/legacy/protocol.py", line 568, in recv
    await self.ensure_open()
  File "/home/sam/Desktop/control_loop/env/lib/python3.10/site-packages/websockets/legacy/protocol.py", line 939, in ensure_open
    raise self.connection_closed_exc()
websockets.exceptions.ConnectionClosedError: no close frame received or sent

2024-07-10 11:23:13 - ERROR - Error in handle_client
Unexpected error: no close frame received or sent
Traceback (most recent call last):
  File "/home/sam/Desktop/control_loop/env/lib/python3.10/site-packages/websockets/legacy/protocol.py", line 963, in transfer_data
    message = await self.read_message()
  File "/home/sam/Desktop/control_loop/env/lib/python3.10/site-packages/websockets/legacy/protocol.py", line 1033, in read_message
    frame = await self.read_data_frame(max_size=self.max_size)
  File "/home/sam/Desktop/control_loop/env/lib/python3.10/site-packages/websockets/legacy/protocol.py", line 1108, in read_data_frame
    frame = await self.read_frame(max_size)
  File "/home/sam/Desktop/control_loop/env/lib/python3.10/site-packages/websockets/legacy/protocol.py", line 1165, in read_frame
    frame = await Frame.read(
  File "/home/sam/Desktop/control_loop/env/lib/python3.10/site-packages/websockets/legacy/framing.py", line 68, in read
    data = await reader(2)
  File "/usr/lib/python3.10/asyncio/streams.py", line 706, in readexactly
    raise exceptions.IncompleteReadError(incomplete, n)
asyncio.exceptions.IncompleteReadError: 0 bytes read on a total of 2 expected bytes

The above exception was the direct cause of the following exception:

Traceback (most recent call last):
  File "/home/sam/Desktop/control_loop/webapp/backend/api_server.py", line 53, in handle_client
    message = await asyncio.wait_for(websocket.recv(), timeout=60)
  File "/usr/lib/python3.10/asyncio/tasks.py", line 445, in wait_for
    return fut.result()
  File "/home/sam/Desktop/control_loop/env/lib/python3.10/site-packages/websockets/legacy/protocol.py", line 568, in recv
    await self.ensure_open()
  File "/home/sam/Desktop/control_loop/env/lib/python3.10/site-packages/websockets/legacy/protocol.py", line 939, in ensure_open
    raise self.connection_closed_exc()
websockets.exceptions.ConnectionClosedError: no close frame received or sent

2024-07-10 11:24:36 - ERROR - Error in handle_client
Unexpected error: no close frame received or sent
Traceback (most recent call last):
  File "/home/sam/Desktop/control_loop/env/lib/python3.10/site-packages/websockets/legacy/protocol.py", line 963, in transfer_data
    message = await self.read_message()
  File "/home/sam/Desktop/control_loop/env/lib/python3.10/site-packages/websockets/legacy/protocol.py", line 1033, in read_message
    frame = await self.read_data_frame(max_size=self.max_size)
  File "/home/sam/Desktop/control_loop/env/lib/python3.10/site-packages/websockets/legacy/protocol.py", line 1108, in read_data_frame
    frame = await self.read_frame(max_size)
  File "/home/sam/Desktop/control_loop/env/lib/python3.10/site-packages/websockets/legacy/protocol.py", line 1165, in read_frame
    frame = await Frame.read(
  File "/home/sam/Desktop/control_loop/env/lib/python3.10/site-packages/websockets/legacy/framing.py", line 68, in read
    data = await reader(2)
  File "/usr/lib/python3.10/asyncio/streams.py", line 706, in readexactly
    raise exceptions.IncompleteReadError(incomplete, n)
asyncio.exceptions.IncompleteReadError: 0 bytes read on a total of 2 expected bytes

The above exception was the direct cause of the following exception:

Traceback (most recent call last):
  File "/home/sam/Desktop/control_loop/webapp/backend/api_server.py", line 53, in handle_client
    message = await asyncio.wait_for(websocket.recv(), timeout=60)
  File "/usr/lib/python3.10/asyncio/tasks.py", line 445, in wait_for
    return fut.result()
  File "/home/sam/Desktop/control_loop/env/lib/python3.10/site-packages/websockets/legacy/protocol.py", line 568, in recv
    await self.ensure_open()
  File "/home/sam/Desktop/control_loop/env/lib/python3.10/site-packages/websockets/legacy/protocol.py", line 939, in ensure_open
    raise self.connection_closed_exc()
websockets.exceptions.ConnectionClosedError: no close frame received or sent

2024-07-10 11:24:56 - ERROR - Error in handle_client
Unexpected error: no close frame received or sent
Traceback (most recent call last):
  File "/home/sam/Desktop/control_loop/env/lib/python3.10/site-packages/websockets/legacy/protocol.py", line 963, in transfer_data
    message = await self.read_message()
  File "/home/sam/Desktop/control_loop/env/lib/python3.10/site-packages/websockets/legacy/protocol.py", line 1033, in read_message
    frame = await self.read_data_frame(max_size=self.max_size)
  File "/home/sam/Desktop/control_loop/env/lib/python3.10/site-packages/websockets/legacy/protocol.py", line 1108, in read_data_frame
    frame = await self.read_frame(max_size)
  File "/home/sam/Desktop/control_loop/env/lib/python3.10/site-packages/websockets/legacy/protocol.py", line 1165, in read_frame
    frame = await Frame.read(
  File "/home/sam/Desktop/control_loop/env/lib/python3.10/site-packages/websockets/legacy/framing.py", line 68, in read
    data = await reader(2)
  File "/usr/lib/python3.10/asyncio/streams.py", line 706, in readexactly
    raise exceptions.IncompleteReadError(incomplete, n)
asyncio.exceptions.IncompleteReadError: 0 bytes read on a total of 2 expected bytes

The above exception was the direct cause of the following exception:

Traceback (most recent call last):
  File "/home/sam/Desktop/control_loop/webapp/backend/api_server.py", line 53, in handle_client
    message = await asyncio.wait_for(websocket.recv(), timeout=60)
  File "/usr/lib/python3.10/asyncio/tasks.py", line 445, in wait_for
    return fut.result()
  File "/home/sam/Desktop/control_loop/env/lib/python3.10/site-packages/websockets/legacy/protocol.py", line 568, in recv
    await self.ensure_open()
  File "/home/sam/Desktop/control_loop/env/lib/python3.10/site-packages/websockets/legacy/protocol.py", line 939, in ensure_open
    raise self.connection_closed_exc()
websockets.exceptions.ConnectionClosedError: no close frame received or sent

2024-07-10 11:28:21 - ERROR - Error in handle_client
Unexpected error: no close frame received or sent
Traceback (most recent call last):
  File "/home/sam/Desktop/control_loop/env/lib/python3.10/site-packages/websockets/legacy/protocol.py", line 963, in transfer_data
    message = await self.read_message()
  File "/home/sam/Desktop/control_loop/env/lib/python3.10/site-packages/websockets/legacy/protocol.py", line 1033, in read_message
    frame = await self.read_data_frame(max_size=self.max_size)
  File "/home/sam/Desktop/control_loop/env/lib/python3.10/site-packages/websockets/legacy/protocol.py", line 1108, in read_data_frame
    frame = await self.read_frame(max_size)
  File "/home/sam/Desktop/control_loop/env/lib/python3.10/site-packages/websockets/legacy/protocol.py", line 1165, in read_frame
    frame = await Frame.read(
  File "/home/sam/Desktop/control_loop/env/lib/python3.10/site-packages/websockets/legacy/framing.py", line 68, in read
    data = await reader(2)
  File "/usr/lib/python3.10/asyncio/streams.py", line 706, in readexactly
    raise exceptions.IncompleteReadError(incomplete, n)
asyncio.exceptions.IncompleteReadError: 0 bytes read on a total of 2 expected bytes

The above exception was the direct cause of the following exception:

Traceback (most recent call last):
  File "/home/sam/Desktop/control_loop/webapp/backend/api_server.py", line 53, in handle_client
    message = await asyncio.wait_for(websocket.recv(), timeout=60)
  File "/usr/lib/python3.10/asyncio/tasks.py", line 445, in wait_for
    return fut.result()
  File "/home/sam/Desktop/control_loop/env/lib/python3.10/site-packages/websockets/legacy/protocol.py", line 568, in recv
    await self.ensure_open()
  File "/home/sam/Desktop/control_loop/env/lib/python3.10/site-packages/websockets/legacy/protocol.py", line 939, in ensure_open
    raise self.connection_closed_exc()
websockets.exceptions.ConnectionClosedError: no close frame received or sent

2024-07-10 11:29:00 - ERROR - Error in handle_client
Unexpected error: no close frame received or sent
Traceback (most recent call last):
  File "/home/sam/Desktop/control_loop/env/lib/python3.10/site-packages/websockets/legacy/protocol.py", line 963, in transfer_data
    message = await self.read_message()
  File "/home/sam/Desktop/control_loop/env/lib/python3.10/site-packages/websockets/legacy/protocol.py", line 1033, in read_message
    frame = await self.read_data_frame(max_size=self.max_size)
  File "/home/sam/Desktop/control_loop/env/lib/python3.10/site-packages/websockets/legacy/protocol.py", line 1108, in read_data_frame
    frame = await self.read_frame(max_size)
  File "/home/sam/Desktop/control_loop/env/lib/python3.10/site-packages/websockets/legacy/protocol.py", line 1165, in read_frame
    frame = await Frame.read(
  File "/home/sam/Desktop/control_loop/env/lib/python3.10/site-packages/websockets/legacy/framing.py", line 68, in read
    data = await reader(2)
  File "/usr/lib/python3.10/asyncio/streams.py", line 706, in readexactly
    raise exceptions.IncompleteReadError(incomplete, n)
asyncio.exceptions.IncompleteReadError: 0 bytes read on a total of 2 expected bytes

The above exception was the direct cause of the following exception:

Traceback (most recent call last):
  File "/home/sam/Desktop/control_loop/webapp/backend/api_server.py", line 53, in handle_client
    message = await asyncio.wait_for(websocket.recv(), timeout=60)
  File "/usr/lib/python3.10/asyncio/tasks.py", line 445, in wait_for
    return fut.result()
  File "/home/sam/Desktop/control_loop/env/lib/python3.10/site-packages/websockets/legacy/protocol.py", line 568, in recv
    await self.ensure_open()
  File "/home/sam/Desktop/control_loop/env/lib/python3.10/site-packages/websockets/legacy/protocol.py", line 939, in ensure_open
    raise self.connection_closed_exc()
websockets.exceptions.ConnectionClosedError: no close frame received or sent

