2024-07-16 14:25:31 - ERROR - Error in handle_client
Unexpected error: received 1001 (going away); then sent 1001 (going away)
Traceback (most recent call last):
  File "/Users/samgupta/Github/control_loop/webapp/backend/api_server.py", line 81, in handle_client
    message = await asyncio.wait_for(websocket.recv(), timeout=60)
              ^^^^^^^^^^^^^^^^^^^^^^^^^^^^^^^^^^^^^^^^^^^^^^^^^^^^
  File "/Library/Frameworks/Python.framework/Versions/3.12/lib/python3.12/asyncio/tasks.py", line 520, in wait_for
    return await fut
           ^^^^^^^^^
  File "/Users/samgupta/Github/control_loop/control_loop/lib/python3.12/site-packages/websockets/legacy/protocol.py", line 568, in recv
    await self.ensure_open()
  File "/Users/samgupta/Github/control_loop/control_loop/lib/python3.12/site-packages/websockets/legacy/protocol.py", line 939, in ensure_open
    raise self.connection_closed_exc()
websockets.exceptions.ConnectionClosedOK: received 1001 (going away); then sent 1001 (going away)

2024-07-16 14:25:31 - ERROR - type of exception: <class 'websockets.exceptions.ConnectionClosedOK'>
2024-07-16 14:25:51 - ERROR - recieved ping from frontend
2024-07-16 14:26:11 - ERROR - recieved ping from frontend
2024-07-16 14:26:31 - ERROR - recieved ping from frontend
2024-07-16 14:26:45 - ERROR - Error in handle_client
Unexpected error: received 1001 (going away); then sent 1001 (going away)
Traceback (most recent call last):
  File "/Users/samgupta/Github/control_loop/webapp/backend/api_server.py", line 81, in handle_client
    message = await asyncio.wait_for(websocket.recv(), timeout=60)
              ^^^^^^^^^^^^^^^^^^^^^^^^^^^^^^^^^^^^^^^^^^^^^^^^^^^^
  File "/Library/Frameworks/Python.framework/Versions/3.12/lib/python3.12/asyncio/tasks.py", line 520, in wait_for
    return await fut
           ^^^^^^^^^
  File "/Users/samgupta/Github/control_loop/control_loop/lib/python3.12/site-packages/websockets/legacy/protocol.py", line 568, in recv
    await self.ensure_open()
  File "/Users/samgupta/Github/control_loop/control_loop/lib/python3.12/site-packages/websockets/legacy/protocol.py", line 939, in ensure_open
    raise self.connection_closed_exc()
websockets.exceptions.ConnectionClosedOK: received 1001 (going away); then sent 1001 (going away)

2024-07-16 14:26:45 - ERROR - type of exception: <class 'websockets.exceptions.ConnectionClosedOK'>
2024-07-16 14:26:58 - ERROR - Error in get_controller: 
 Input: concentrationLoopIdentifier, 
 cannot access local variable 'controller' where it is not associated with a value
Traceback (most recent call last):
  File "/Users/samgupta/Github/control_loop/webapp/backend/manager_server.py", line 269, in get_controller
    controller = c.create_controller(loop_id)
                 ^^^^^^^^^^^^^^^^^^^^^^^^^^^^
  File "/Users/samgupta/Github/control_loop/webapp/backend/../../src/controllers_mqtt.py", line 43, in create_controller
    return controller
           ^^^^^^^^^^
UnboundLocalError: cannot access local variable 'controller' where it is not associated with a value

2024-07-16 14:26:58 - ERROR - Error in toggle: 
 Input: toggle_buffer_pump, 
'NoneType' object is not subscriptable
Traceback (most recent call last):
  File "/Users/samgupta/Github/control_loop/webapp/backend/manager_server.py", line 170, in toggle
    controller_info["controller"].toggle_pump(pump_name + "_pump")
    ~~~~~~~~~~~~~~~^^^^^^^^^^^^^^
TypeError: 'NoneType' object is not subscriptable

2024-07-16 14:27:05 - ERROR - recieved ping from frontend
2024-07-16 14:27:25 - ERROR - recieved ping from frontend
2024-07-16 14:27:45 - ERROR - recieved ping from frontend
2024-07-16 14:28:05 - ERROR - recieved ping from frontend
2024-07-16 14:28:25 - ERROR - recieved ping from frontend
2024-07-16 14:28:45 - ERROR - recieved ping from frontend
2024-07-16 14:29:05 - ERROR - recieved ping from frontend
2024-07-16 14:30:03 - ERROR - Error in handle_client
Unexpected error: received 1001 (going away); then sent 1001 (going away)
Traceback (most recent call last):
  File "/Users/samgupta/Github/control_loop/webapp/backend/api_server.py", line 81, in handle_client
    message = await asyncio.wait_for(websocket.recv(), timeout=60)
              ^^^^^^^^^^^^^^^^^^^^^^^^^^^^^^^^^^^^^^^^^^^^^^^^^^^^
  File "/Library/Frameworks/Python.framework/Versions/3.12/lib/python3.12/asyncio/tasks.py", line 520, in wait_for
    return await fut
           ^^^^^^^^^
  File "/Users/samgupta/Github/control_loop/control_loop/lib/python3.12/site-packages/websockets/legacy/protocol.py", line 568, in recv
    await self.ensure_open()
  File "/Users/samgupta/Github/control_loop/control_loop/lib/python3.12/site-packages/websockets/legacy/protocol.py", line 939, in ensure_open
    raise self.connection_closed_exc()
websockets.exceptions.ConnectionClosedOK: received 1001 (going away); then sent 1001 (going away)

2024-07-16 14:30:03 - ERROR - type of exception: <class 'websockets.exceptions.ConnectionClosedOK'>
2024-07-16 14:30:13 - ERROR - Error in get_controller: 
 Input: concentration_loop, 
 timed out
Traceback (most recent call last):
  File "/Users/samgupta/Github/control_loop/webapp/backend/manager_server.py", line 269, in get_controller
    controller = c.create_controller(loop_id)
                 ^^^^^^^^^^^^^^^^^^^^^^^^^^^^
  File "/Users/samgupta/Github/control_loop/webapp/backend/../../src/controllers_mqtt.py", line 39, in create_controller
    controller = ConcentrationController()
                 ^^^^^^^^^^^^^^^^^^^^^^^^^
  File "/Users/samgupta/Github/control_loop/webapp/backend/../../src/controllers_mqtt.py", line 444, in __init__
    self.mqtt_client = ControllerMQTTClient(broker_address="192.168.0.25")
                       ^^^^^^^^^^^^^^^^^^^^^^^^^^^^^^^^^^^^^^^^^^^^^^^^^^^
  File "/Users/samgupta/Github/control_loop/webapp/backend/../../src/controller_mqtt_client.py", line 9, in __init__
    self.client.connect(broker_address, 1883, 60)
  File "/Users/samgupta/Github/control_loop/control_loop/lib/python3.12/site-packages/paho/mqtt/client.py", line 1435, in connect
    return self.reconnect()
           ^^^^^^^^^^^^^^^^
  File "/Users/samgupta/Github/control_loop/control_loop/lib/python3.12/site-packages/paho/mqtt/client.py", line 1598, in reconnect
    self._sock = self._create_socket()
                 ^^^^^^^^^^^^^^^^^^^^^
  File "/Users/samgupta/Github/control_loop/control_loop/lib/python3.12/site-packages/paho/mqtt/client.py", line 4609, in _create_socket
    sock = self._create_socket_connection()
           ^^^^^^^^^^^^^^^^^^^^^^^^^^^^^^^^
  File "/Users/samgupta/Github/control_loop/control_loop/lib/python3.12/site-packages/paho/mqtt/client.py", line 4640, in _create_socket_connection
    return socket.create_connection(addr, timeout=self._connect_timeout, source_address=source)
           ^^^^^^^^^^^^^^^^^^^^^^^^^^^^^^^^^^^^^^^^^^^^^^^^^^^^^^^^^^^^^^^^^^^^^^^^^^^^^^^^^^^^
  File "/Library/Frameworks/Python.framework/Versions/3.12/lib/python3.12/socket.py", line 853, in create_connection
    raise exceptions[0]
  File "/Library/Frameworks/Python.framework/Versions/3.12/lib/python3.12/socket.py", line 838, in create_connection
    sock.connect(sa)
TimeoutError: timed out

2024-07-16 14:30:13 - ERROR - Error in toggle: 
 Input: toggle_buffer_pump, 
'NoneType' object is not subscriptable
Traceback (most recent call last):
  File "/Users/samgupta/Github/control_loop/webapp/backend/manager_server.py", line 170, in toggle
    controller_info["controller"].toggle_pump(pump_name + "_pump")
    ~~~~~~~~~~~~~~~^^^^^^^^^^^^^^
TypeError: 'NoneType' object is not subscriptable

2024-07-16 14:30:23 - ERROR - recieved ping from frontend
2024-07-16 14:30:43 - ERROR - recieved ping from frontend
2024-07-16 14:31:03 - ERROR - recieved ping from frontend
2024-07-16 14:31:23 - ERROR - recieved ping from frontend
2024-07-16 14:31:43 - ERROR - recieved ping from frontend
2024-07-16 14:32:22 - ERROR - Error in handle_client
Unexpected error: received 1001 (going away); then sent 1001 (going away)
Traceback (most recent call last):
  File "/Users/samgupta/Github/control_loop/webapp/backend/api_server.py", line 81, in handle_client
    message = await asyncio.wait_for(websocket.recv(), timeout=60)
              ^^^^^^^^^^^^^^^^^^^^^^^^^^^^^^^^^^^^^^^^^^^^^^^^^^^^
  File "/Library/Frameworks/Python.framework/Versions/3.12/lib/python3.12/asyncio/tasks.py", line 520, in wait_for
    return await fut
           ^^^^^^^^^
  File "/Users/samgupta/Github/control_loop/control_loop/lib/python3.12/site-packages/websockets/legacy/protocol.py", line 568, in recv
    await self.ensure_open()
  File "/Users/samgupta/Github/control_loop/control_loop/lib/python3.12/site-packages/websockets/legacy/protocol.py", line 939, in ensure_open
    raise self.connection_closed_exc()
websockets.exceptions.ConnectionClosedOK: received 1001 (going away); then sent 1001 (going away)

2024-07-16 14:32:22 - ERROR - type of exception: <class 'websockets.exceptions.ConnectionClosedOK'>
