2024-07-23 12:09:15 - ERROR - Error in handle_client
Unexpected error: sent 1001 (going away) Server shutdown; then received 1001 (going away) Server shutdown
Traceback (most recent call last):
  File "/Users/samgupta/Github/control_loop/webapp/backend/api_server.py", line 127, in handle_client
    message = await asyncio.wait_for(websocket.recv(), timeout=60)
              ^^^^^^^^^^^^^^^^^^^^^^^^^^^^^^^^^^^^^^^^^^^^^^^^^^^^
  File "/Library/Frameworks/Python.framework/Versions/3.12/lib/python3.12/asyncio/tasks.py", line 520, in wait_for
    return await fut
           ^^^^^^^^^
  File "/Users/samgupta/Github/control_loop/control_loop/lib/python3.12/site-packages/websockets/legacy/protocol.py", line 568, in recv
    await self.ensure_open()
  File "/Users/samgupta/Github/control_loop/control_loop/lib/python3.12/site-packages/websockets/legacy/protocol.py", line 948, in ensure_open
    raise self.connection_closed_exc()
websockets.exceptions.ConnectionClosedOK: sent 1001 (going away) Server shutdown; then received 1001 (going away) Server shutdown

2024-07-23 12:09:15 - ERROR - type of exception: <class 'websockets.exceptions.ConnectionClosedOK'>
2024-07-23 12:09:15 - ERROR - Error in send_notification: 'NoneType' object has no attribute 'raw'
Traceback (most recent call last):
  File "/Users/samgupta/Github/control_loop/webapp/backend/api_server.py", line 127, in handle_client
    message = await asyncio.wait_for(websocket.recv(), timeout=60)
              ^^^^^^^^^^^^^^^^^^^^^^^^^^^^^^^^^^^^^^^^^^^^^^^^^^^^
  File "/Library/Frameworks/Python.framework/Versions/3.12/lib/python3.12/asyncio/tasks.py", line 520, in wait_for
    return await fut
           ^^^^^^^^^
  File "/Users/samgupta/Github/control_loop/control_loop/lib/python3.12/site-packages/websockets/legacy/protocol.py", line 568, in recv
    await self.ensure_open()
  File "/Users/samgupta/Github/control_loop/control_loop/lib/python3.12/site-packages/websockets/legacy/protocol.py", line 948, in ensure_open
    raise self.connection_closed_exc()
websockets.exceptions.ConnectionClosedOK: sent 1001 (going away) Server shutdown; then received 1001 (going away) Server shutdown

During handling of the above exception, another exception occurred:

Traceback (most recent call last):
  File "/Users/samgupta/Github/control_loop/webapp/backend/../../src/resources/error_notification.py", line 17, in send_notification
    print(app.is_authenticated)
          ^^^^^^^^^^^^^^^^^^^^
  File "/Users/samgupta/Github/control_loop/control_loop/lib/python3.12/site-packages/chump/__init__.py", line 200, in is_authenticated
    self._authenticate()
  File "/Users/samgupta/Github/control_loop/control_loop/lib/python3.12/site-packages/chump/__init__.py", line 273, in _authenticate
    self._sounds = self._request('sound')[0]['sounds']
                   ^^^^^^^^^^^^^^^^^^^^^^
  File "/Users/samgupta/Github/control_loop/control_loop/lib/python3.12/site-packages/chump/__init__.py", line 334, in _request
    response = pool.open(url)
               ^^^^^^^^^^^^^^
  File "/Library/Frameworks/Python.framework/Versions/3.12/lib/python3.12/urllib/request.py", line 515, in open
    response = self._open(req, data)
               ^^^^^^^^^^^^^^^^^^^^^
  File "/Library/Frameworks/Python.framework/Versions/3.12/lib/python3.12/urllib/request.py", line 532, in _open
    result = self._call_chain(self.handle_open, protocol, protocol +
             ^^^^^^^^^^^^^^^^^^^^^^^^^^^^^^^^^^^^^^^^^^^^^^^^^^^^^^^
  File "/Library/Frameworks/Python.framework/Versions/3.12/lib/python3.12/urllib/request.py", line 492, in _call_chain
    result = func(*args)
             ^^^^^^^^^^^
  File "/Users/samgupta/Github/control_loop/control_loop/lib/python3.12/site-packages/chump/connection_pool.py", line 82, in https_open
    if response.raw.will_close:
       ^^^^^^^^^^^^
AttributeError: 'NoneType' object has no attribute 'raw'

2024-07-23 12:09:15 - ERROR - Backup Server Starting
2024-07-23 12:09:53 - ERROR - Error in handle_client
Unexpected error: received 1001 (going away); then sent 1001 (going away)
Traceback (most recent call last):
  File "/Users/samgupta/Github/control_loop/webapp/backend/api_server.py", line 127, in handle_client
    message = await asyncio.wait_for(websocket.recv(), timeout=60)
              ^^^^^^^^^^^^^^^^^^^^^^^^^^^^^^^^^^^^^^^^^^^^^^^^^^^^
  File "/Library/Frameworks/Python.framework/Versions/3.12/lib/python3.12/asyncio/tasks.py", line 520, in wait_for
    return await fut
           ^^^^^^^^^
  File "/Users/samgupta/Github/control_loop/control_loop/lib/python3.12/site-packages/websockets/legacy/protocol.py", line 568, in recv
    await self.ensure_open()
  File "/Users/samgupta/Github/control_loop/control_loop/lib/python3.12/site-packages/websockets/legacy/protocol.py", line 939, in ensure_open
    raise self.connection_closed_exc()
websockets.exceptions.ConnectionClosedOK: received 1001 (going away); then sent 1001 (going away)

2024-07-23 12:09:53 - ERROR - type of exception: <class 'websockets.exceptions.ConnectionClosedOK'>
2024-07-23 12:09:53 - ERROR - Error in send_notification: 'NoneType' object has no attribute 'raw'
Traceback (most recent call last):
  File "/Users/samgupta/Github/control_loop/webapp/backend/api_server.py", line 127, in handle_client
    message = await asyncio.wait_for(websocket.recv(), timeout=60)
              ^^^^^^^^^^^^^^^^^^^^^^^^^^^^^^^^^^^^^^^^^^^^^^^^^^^^
  File "/Library/Frameworks/Python.framework/Versions/3.12/lib/python3.12/asyncio/tasks.py", line 520, in wait_for
    return await fut
           ^^^^^^^^^
  File "/Users/samgupta/Github/control_loop/control_loop/lib/python3.12/site-packages/websockets/legacy/protocol.py", line 568, in recv
    await self.ensure_open()
  File "/Users/samgupta/Github/control_loop/control_loop/lib/python3.12/site-packages/websockets/legacy/protocol.py", line 939, in ensure_open
    raise self.connection_closed_exc()
websockets.exceptions.ConnectionClosedOK: received 1001 (going away); then sent 1001 (going away)

During handling of the above exception, another exception occurred:

Traceback (most recent call last):
  File "/Users/samgupta/Github/control_loop/webapp/backend/../../src/resources/error_notification.py", line 17, in send_notification
    print(app.is_authenticated)
          ^^^^^^^^^^^^^^^^^^^^
  File "/Users/samgupta/Github/control_loop/control_loop/lib/python3.12/site-packages/chump/__init__.py", line 200, in is_authenticated
    self._authenticate()
  File "/Users/samgupta/Github/control_loop/control_loop/lib/python3.12/site-packages/chump/__init__.py", line 273, in _authenticate
    self._sounds = self._request('sound')[0]['sounds']
                   ^^^^^^^^^^^^^^^^^^^^^^
  File "/Users/samgupta/Github/control_loop/control_loop/lib/python3.12/site-packages/chump/__init__.py", line 334, in _request
    response = pool.open(url)
               ^^^^^^^^^^^^^^
  File "/Library/Frameworks/Python.framework/Versions/3.12/lib/python3.12/urllib/request.py", line 515, in open
    response = self._open(req, data)
               ^^^^^^^^^^^^^^^^^^^^^
  File "/Library/Frameworks/Python.framework/Versions/3.12/lib/python3.12/urllib/request.py", line 532, in _open
    result = self._call_chain(self.handle_open, protocol, protocol +
             ^^^^^^^^^^^^^^^^^^^^^^^^^^^^^^^^^^^^^^^^^^^^^^^^^^^^^^^
  File "/Library/Frameworks/Python.framework/Versions/3.12/lib/python3.12/urllib/request.py", line 492, in _call_chain
    result = func(*args)
             ^^^^^^^^^^^
  File "/Users/samgupta/Github/control_loop/control_loop/lib/python3.12/site-packages/chump/connection_pool.py", line 82, in https_open
    if response.raw.will_close:
       ^^^^^^^^^^^^
AttributeError: 'NoneType' object has no attribute 'raw'

2024-07-23 12:09:53 - ERROR - Backup Server Starting
2024-07-23 12:10:02 - ERROR - Error in send_notification: 'NoneType' object has no attribute 'raw'
Traceback (most recent call last):
  File "/Users/samgupta/Github/control_loop/webapp/backend/api_server.py", line 127, in handle_client
    message = await asyncio.wait_for(websocket.recv(), timeout=60)
              ^^^^^^^^^^^^^^^^^^^^^^^^^^^^^^^^^^^^^^^^^^^^^^^^^^^^
  File "/Library/Frameworks/Python.framework/Versions/3.12/lib/python3.12/asyncio/tasks.py", line 520, in wait_for
    return await fut
           ^^^^^^^^^
  File "/Users/samgupta/Github/control_loop/control_loop/lib/python3.12/site-packages/websockets/legacy/protocol.py", line 568, in recv
    await self.ensure_open()
  File "/Users/samgupta/Github/control_loop/control_loop/lib/python3.12/site-packages/websockets/legacy/protocol.py", line 939, in ensure_open
    raise self.connection_closed_exc()
websockets.exceptions.ConnectionClosedOK: received 1001 (going away); then sent 1001 (going away)

During handling of the above exception, another exception occurred:

Traceback (most recent call last):
  File "/Users/samgupta/Github/control_loop/webapp/backend/../../src/resources/error_notification.py", line 17, in send_notification
    print(app.is_authenticated)
          ^^^^^^^^^^^^^^^^^^^^
  File "/Users/samgupta/Github/control_loop/control_loop/lib/python3.12/site-packages/chump/__init__.py", line 200, in is_authenticated
    self._authenticate()
  File "/Users/samgupta/Github/control_loop/control_loop/lib/python3.12/site-packages/chump/__init__.py", line 273, in _authenticate
    self._sounds = self._request('sound')[0]['sounds']
                   ^^^^^^^^^^^^^^^^^^^^^^
  File "/Users/samgupta/Github/control_loop/control_loop/lib/python3.12/site-packages/chump/__init__.py", line 334, in _request
    response = pool.open(url)
               ^^^^^^^^^^^^^^
  File "/Library/Frameworks/Python.framework/Versions/3.12/lib/python3.12/urllib/request.py", line 515, in open
    response = self._open(req, data)
               ^^^^^^^^^^^^^^^^^^^^^
  File "/Library/Frameworks/Python.framework/Versions/3.12/lib/python3.12/urllib/request.py", line 532, in _open
    result = self._call_chain(self.handle_open, protocol, protocol +
             ^^^^^^^^^^^^^^^^^^^^^^^^^^^^^^^^^^^^^^^^^^^^^^^^^^^^^^^
  File "/Library/Frameworks/Python.framework/Versions/3.12/lib/python3.12/urllib/request.py", line 492, in _call_chain
    result = func(*args)
             ^^^^^^^^^^^
  File "/Users/samgupta/Github/control_loop/control_loop/lib/python3.12/site-packages/chump/connection_pool.py", line 82, in https_open
    if response.raw.will_close:
       ^^^^^^^^^^^^
AttributeError: 'NoneType' object has no attribute 'raw'

2024-07-23 12:18:47 - ERROR - Error in handle_client
Unexpected error: sent 1001 (going away) Server shutdown; then received 1001 (going away) Server shutdown
Traceback (most recent call last):
  File "/Users/samgupta/Github/control_loop/webapp/backend/api_server.py", line 127, in handle_client
    message = await asyncio.wait_for(websocket.recv(), timeout=60)
              ^^^^^^^^^^^^^^^^^^^^^^^^^^^^^^^^^^^^^^^^^^^^^^^^^^^^
  File "/Library/Frameworks/Python.framework/Versions/3.12/lib/python3.12/asyncio/tasks.py", line 520, in wait_for
    return await fut
           ^^^^^^^^^
  File "/Users/samgupta/Github/control_loop/control_loop/lib/python3.12/site-packages/websockets/legacy/protocol.py", line 568, in recv
    await self.ensure_open()
  File "/Users/samgupta/Github/control_loop/control_loop/lib/python3.12/site-packages/websockets/legacy/protocol.py", line 948, in ensure_open
    raise self.connection_closed_exc()
websockets.exceptions.ConnectionClosedOK: sent 1001 (going away) Server shutdown; then received 1001 (going away) Server shutdown

2024-07-23 12:18:47 - ERROR - type of exception: <class 'websockets.exceptions.ConnectionClosedOK'>
2024-07-23 12:18:47 - ERROR - Error in send_notification: 'NoneType' object has no attribute 'raw'
Traceback (most recent call last):
  File "/Users/samgupta/Github/control_loop/webapp/backend/api_server.py", line 127, in handle_client
    message = await asyncio.wait_for(websocket.recv(), timeout=60)
              ^^^^^^^^^^^^^^^^^^^^^^^^^^^^^^^^^^^^^^^^^^^^^^^^^^^^
  File "/Library/Frameworks/Python.framework/Versions/3.12/lib/python3.12/asyncio/tasks.py", line 520, in wait_for
    return await fut
           ^^^^^^^^^
  File "/Users/samgupta/Github/control_loop/control_loop/lib/python3.12/site-packages/websockets/legacy/protocol.py", line 568, in recv
    await self.ensure_open()
  File "/Users/samgupta/Github/control_loop/control_loop/lib/python3.12/site-packages/websockets/legacy/protocol.py", line 948, in ensure_open
    raise self.connection_closed_exc()
websockets.exceptions.ConnectionClosedOK: sent 1001 (going away) Server shutdown; then received 1001 (going away) Server shutdown

During handling of the above exception, another exception occurred:

Traceback (most recent call last):
  File "/Users/samgupta/Github/control_loop/webapp/backend/../../src/resources/error_notification.py", line 17, in send_notification
    print(app.is_authenticated)
          ^^^^^^^^^^^^^^^^^^^^
  File "/Users/samgupta/Github/control_loop/control_loop/lib/python3.12/site-packages/chump/__init__.py", line 200, in is_authenticated
    self._authenticate()
  File "/Users/samgupta/Github/control_loop/control_loop/lib/python3.12/site-packages/chump/__init__.py", line 273, in _authenticate
    self._sounds = self._request('sound')[0]['sounds']
                   ^^^^^^^^^^^^^^^^^^^^^^
  File "/Users/samgupta/Github/control_loop/control_loop/lib/python3.12/site-packages/chump/__init__.py", line 334, in _request
    response = pool.open(url)
               ^^^^^^^^^^^^^^
  File "/Library/Frameworks/Python.framework/Versions/3.12/lib/python3.12/urllib/request.py", line 515, in open
    response = self._open(req, data)
               ^^^^^^^^^^^^^^^^^^^^^
  File "/Library/Frameworks/Python.framework/Versions/3.12/lib/python3.12/urllib/request.py", line 532, in _open
    result = self._call_chain(self.handle_open, protocol, protocol +
             ^^^^^^^^^^^^^^^^^^^^^^^^^^^^^^^^^^^^^^^^^^^^^^^^^^^^^^^
  File "/Library/Frameworks/Python.framework/Versions/3.12/lib/python3.12/urllib/request.py", line 492, in _call_chain
    result = func(*args)
             ^^^^^^^^^^^
  File "/Users/samgupta/Github/control_loop/control_loop/lib/python3.12/site-packages/chump/connection_pool.py", line 82, in https_open
    if response.raw.will_close:
       ^^^^^^^^^^^^
AttributeError: 'NoneType' object has no attribute 'raw'

2024-07-23 12:18:47 - ERROR - Backup Server Starting
2024-07-23 13:17:44 - ERROR - Error in handle_client
Unexpected error: received 1001 (going away); then sent 1001 (going away)
Traceback (most recent call last):
  File "/Users/samgupta/Github/control_loop/webapp/backend/api_server.py", line 127, in handle_client
    message = await asyncio.wait_for(websocket.recv(), timeout=60)
              ^^^^^^^^^^^^^^^^^^^^^^^^^^^^^^^^^^^^^^^^^^^^^^^^^^^^
  File "/Library/Frameworks/Python.framework/Versions/3.12/lib/python3.12/asyncio/tasks.py", line 520, in wait_for
    return await fut
           ^^^^^^^^^
  File "/Users/samgupta/Github/control_loop/control_loop/lib/python3.12/site-packages/websockets/legacy/protocol.py", line 568, in recv
    await self.ensure_open()
  File "/Users/samgupta/Github/control_loop/control_loop/lib/python3.12/site-packages/websockets/legacy/protocol.py", line 939, in ensure_open
    raise self.connection_closed_exc()
websockets.exceptions.ConnectionClosedOK: received 1001 (going away); then sent 1001 (going away)

2024-07-23 13:17:44 - ERROR - type of exception: <class 'websockets.exceptions.ConnectionClosedOK'>
2024-07-23 13:17:45 - ERROR - Error in send_notification: 'NoneType' object has no attribute 'raw'
Traceback (most recent call last):
  File "/Users/samgupta/Github/control_loop/webapp/backend/api_server.py", line 127, in handle_client
    message = await asyncio.wait_for(websocket.recv(), timeout=60)
              ^^^^^^^^^^^^^^^^^^^^^^^^^^^^^^^^^^^^^^^^^^^^^^^^^^^^
  File "/Library/Frameworks/Python.framework/Versions/3.12/lib/python3.12/asyncio/tasks.py", line 520, in wait_for
    return await fut
           ^^^^^^^^^
  File "/Users/samgupta/Github/control_loop/control_loop/lib/python3.12/site-packages/websockets/legacy/protocol.py", line 568, in recv
    await self.ensure_open()
  File "/Users/samgupta/Github/control_loop/control_loop/lib/python3.12/site-packages/websockets/legacy/protocol.py", line 939, in ensure_open
    raise self.connection_closed_exc()
websockets.exceptions.ConnectionClosedOK: received 1001 (going away); then sent 1001 (going away)

During handling of the above exception, another exception occurred:

Traceback (most recent call last):
  File "/Users/samgupta/Github/control_loop/webapp/backend/../../src/resources/error_notification.py", line 17, in send_notification
    print(app.is_authenticated)
          ^^^^^^^^^^^^^^^^^^^^
  File "/Users/samgupta/Github/control_loop/control_loop/lib/python3.12/site-packages/chump/__init__.py", line 200, in is_authenticated
    self._authenticate()
  File "/Users/samgupta/Github/control_loop/control_loop/lib/python3.12/site-packages/chump/__init__.py", line 273, in _authenticate
    self._sounds = self._request('sound')[0]['sounds']
                   ^^^^^^^^^^^^^^^^^^^^^^
  File "/Users/samgupta/Github/control_loop/control_loop/lib/python3.12/site-packages/chump/__init__.py", line 334, in _request
    response = pool.open(url)
               ^^^^^^^^^^^^^^
  File "/Library/Frameworks/Python.framework/Versions/3.12/lib/python3.12/urllib/request.py", line 515, in open
    response = self._open(req, data)
               ^^^^^^^^^^^^^^^^^^^^^
  File "/Library/Frameworks/Python.framework/Versions/3.12/lib/python3.12/urllib/request.py", line 532, in _open
    result = self._call_chain(self.handle_open, protocol, protocol +
             ^^^^^^^^^^^^^^^^^^^^^^^^^^^^^^^^^^^^^^^^^^^^^^^^^^^^^^^
  File "/Library/Frameworks/Python.framework/Versions/3.12/lib/python3.12/urllib/request.py", line 492, in _call_chain
    result = func(*args)
             ^^^^^^^^^^^
  File "/Users/samgupta/Github/control_loop/control_loop/lib/python3.12/site-packages/chump/connection_pool.py", line 82, in https_open
    if response.raw.will_close:
       ^^^^^^^^^^^^
AttributeError: 'NoneType' object has no attribute 'raw'

2024-07-23 13:17:45 - ERROR - Backup Server Starting
2024-07-23 13:17:53 - ERROR - Error in send_notification: 'NoneType' object has no attribute 'raw'
Traceback (most recent call last):
  File "/Users/samgupta/Github/control_loop/webapp/backend/api_server.py", line 127, in handle_client
    message = await asyncio.wait_for(websocket.recv(), timeout=60)
              ^^^^^^^^^^^^^^^^^^^^^^^^^^^^^^^^^^^^^^^^^^^^^^^^^^^^
  File "/Library/Frameworks/Python.framework/Versions/3.12/lib/python3.12/asyncio/tasks.py", line 520, in wait_for
    return await fut
           ^^^^^^^^^
  File "/Users/samgupta/Github/control_loop/control_loop/lib/python3.12/site-packages/websockets/legacy/protocol.py", line 568, in recv
    await self.ensure_open()
  File "/Users/samgupta/Github/control_loop/control_loop/lib/python3.12/site-packages/websockets/legacy/protocol.py", line 939, in ensure_open
    raise self.connection_closed_exc()
websockets.exceptions.ConnectionClosedOK: received 1001 (going away); then sent 1001 (going away)

During handling of the above exception, another exception occurred:

Traceback (most recent call last):
  File "/Users/samgupta/Github/control_loop/webapp/backend/../../src/resources/error_notification.py", line 17, in send_notification
    print(app.is_authenticated)
          ^^^^^^^^^^^^^^^^^^^^
  File "/Users/samgupta/Github/control_loop/control_loop/lib/python3.12/site-packages/chump/__init__.py", line 200, in is_authenticated
    self._authenticate()
  File "/Users/samgupta/Github/control_loop/control_loop/lib/python3.12/site-packages/chump/__init__.py", line 273, in _authenticate
    self._sounds = self._request('sound')[0]['sounds']
                   ^^^^^^^^^^^^^^^^^^^^^^
  File "/Users/samgupta/Github/control_loop/control_loop/lib/python3.12/site-packages/chump/__init__.py", line 334, in _request
    response = pool.open(url)
               ^^^^^^^^^^^^^^
  File "/Library/Frameworks/Python.framework/Versions/3.12/lib/python3.12/urllib/request.py", line 515, in open
    response = self._open(req, data)
               ^^^^^^^^^^^^^^^^^^^^^
  File "/Library/Frameworks/Python.framework/Versions/3.12/lib/python3.12/urllib/request.py", line 532, in _open
    result = self._call_chain(self.handle_open, protocol, protocol +
             ^^^^^^^^^^^^^^^^^^^^^^^^^^^^^^^^^^^^^^^^^^^^^^^^^^^^^^^
  File "/Library/Frameworks/Python.framework/Versions/3.12/lib/python3.12/urllib/request.py", line 492, in _call_chain
    result = func(*args)
             ^^^^^^^^^^^
  File "/Users/samgupta/Github/control_loop/control_loop/lib/python3.12/site-packages/chump/connection_pool.py", line 82, in https_open
    if response.raw.will_close:
       ^^^^^^^^^^^^
AttributeError: 'NoneType' object has no attribute 'raw'

2024-07-23 13:21:45 - ERROR - Error in handle_client
Unexpected error: sent 1001 (going away) Server shutdown; then received 1001 (going away) Server shutdown
Traceback (most recent call last):
  File "/Users/samgupta/Github/control_loop/webapp/backend/api_server.py", line 127, in handle_client
    message = await asyncio.wait_for(websocket.recv(), timeout=60)
              ^^^^^^^^^^^^^^^^^^^^^^^^^^^^^^^^^^^^^^^^^^^^^^^^^^^^
  File "/Library/Frameworks/Python.framework/Versions/3.12/lib/python3.12/asyncio/tasks.py", line 520, in wait_for
    return await fut
           ^^^^^^^^^
  File "/Users/samgupta/Github/control_loop/control_loop/lib/python3.12/site-packages/websockets/legacy/protocol.py", line 568, in recv
    await self.ensure_open()
  File "/Users/samgupta/Github/control_loop/control_loop/lib/python3.12/site-packages/websockets/legacy/protocol.py", line 948, in ensure_open
    raise self.connection_closed_exc()
websockets.exceptions.ConnectionClosedOK: sent 1001 (going away) Server shutdown; then received 1001 (going away) Server shutdown

2024-07-23 13:21:45 - ERROR - type of exception: <class 'websockets.exceptions.ConnectionClosedOK'>
2024-07-23 13:21:45 - ERROR - Error in send_notification: 'NoneType' object has no attribute 'raw'
Traceback (most recent call last):
  File "/Users/samgupta/Github/control_loop/webapp/backend/api_server.py", line 127, in handle_client
    message = await asyncio.wait_for(websocket.recv(), timeout=60)
              ^^^^^^^^^^^^^^^^^^^^^^^^^^^^^^^^^^^^^^^^^^^^^^^^^^^^
  File "/Library/Frameworks/Python.framework/Versions/3.12/lib/python3.12/asyncio/tasks.py", line 520, in wait_for
    return await fut
           ^^^^^^^^^
  File "/Users/samgupta/Github/control_loop/control_loop/lib/python3.12/site-packages/websockets/legacy/protocol.py", line 568, in recv
    await self.ensure_open()
  File "/Users/samgupta/Github/control_loop/control_loop/lib/python3.12/site-packages/websockets/legacy/protocol.py", line 948, in ensure_open
    raise self.connection_closed_exc()
websockets.exceptions.ConnectionClosedOK: sent 1001 (going away) Server shutdown; then received 1001 (going away) Server shutdown

During handling of the above exception, another exception occurred:

Traceback (most recent call last):
  File "/Users/samgupta/Github/control_loop/webapp/backend/../../src/resources/error_notification.py", line 17, in send_notification
    print(app.is_authenticated)
          ^^^^^^^^^^^^^^^^^^^^
  File "/Users/samgupta/Github/control_loop/control_loop/lib/python3.12/site-packages/chump/__init__.py", line 200, in is_authenticated
    self._authenticate()
  File "/Users/samgupta/Github/control_loop/control_loop/lib/python3.12/site-packages/chump/__init__.py", line 273, in _authenticate
    self._sounds = self._request('sound')[0]['sounds']
                   ^^^^^^^^^^^^^^^^^^^^^^
  File "/Users/samgupta/Github/control_loop/control_loop/lib/python3.12/site-packages/chump/__init__.py", line 334, in _request
    response = pool.open(url)
               ^^^^^^^^^^^^^^
  File "/Library/Frameworks/Python.framework/Versions/3.12/lib/python3.12/urllib/request.py", line 515, in open
    response = self._open(req, data)
               ^^^^^^^^^^^^^^^^^^^^^
  File "/Library/Frameworks/Python.framework/Versions/3.12/lib/python3.12/urllib/request.py", line 532, in _open
    result = self._call_chain(self.handle_open, protocol, protocol +
             ^^^^^^^^^^^^^^^^^^^^^^^^^^^^^^^^^^^^^^^^^^^^^^^^^^^^^^^
  File "/Library/Frameworks/Python.framework/Versions/3.12/lib/python3.12/urllib/request.py", line 492, in _call_chain
    result = func(*args)
             ^^^^^^^^^^^
  File "/Users/samgupta/Github/control_loop/control_loop/lib/python3.12/site-packages/chump/connection_pool.py", line 82, in https_open
    if response.raw.will_close:
       ^^^^^^^^^^^^
AttributeError: 'NoneType' object has no attribute 'raw'

2024-07-23 13:21:45 - ERROR - Backup Server Starting
2024-07-23 13:21:50 - ERROR - Error in handle_client
Unexpected error: received 1001 (going away); then sent 1001 (going away)
Traceback (most recent call last):
  File "/Users/samgupta/Github/control_loop/webapp/backend/api_server.py", line 127, in handle_client
    message = await asyncio.wait_for(websocket.recv(), timeout=60)
              ^^^^^^^^^^^^^^^^^^^^^^^^^^^^^^^^^^^^^^^^^^^^^^^^^^^^
  File "/Library/Frameworks/Python.framework/Versions/3.12/lib/python3.12/asyncio/tasks.py", line 520, in wait_for
    return await fut
           ^^^^^^^^^
  File "/Users/samgupta/Github/control_loop/control_loop/lib/python3.12/site-packages/websockets/legacy/protocol.py", line 568, in recv
    await self.ensure_open()
  File "/Users/samgupta/Github/control_loop/control_loop/lib/python3.12/site-packages/websockets/legacy/protocol.py", line 939, in ensure_open
    raise self.connection_closed_exc()
websockets.exceptions.ConnectionClosedOK: received 1001 (going away); then sent 1001 (going away)

2024-07-23 13:21:50 - ERROR - type of exception: <class 'websockets.exceptions.ConnectionClosedOK'>
2024-07-23 13:21:50 - ERROR - Error in send_notification: 'NoneType' object has no attribute 'raw'
Traceback (most recent call last):
  File "/Users/samgupta/Github/control_loop/webapp/backend/api_server.py", line 127, in handle_client
    message = await asyncio.wait_for(websocket.recv(), timeout=60)
              ^^^^^^^^^^^^^^^^^^^^^^^^^^^^^^^^^^^^^^^^^^^^^^^^^^^^
  File "/Library/Frameworks/Python.framework/Versions/3.12/lib/python3.12/asyncio/tasks.py", line 520, in wait_for
    return await fut
           ^^^^^^^^^
  File "/Users/samgupta/Github/control_loop/control_loop/lib/python3.12/site-packages/websockets/legacy/protocol.py", line 568, in recv
    await self.ensure_open()
  File "/Users/samgupta/Github/control_loop/control_loop/lib/python3.12/site-packages/websockets/legacy/protocol.py", line 939, in ensure_open
    raise self.connection_closed_exc()
websockets.exceptions.ConnectionClosedOK: received 1001 (going away); then sent 1001 (going away)

During handling of the above exception, another exception occurred:

Traceback (most recent call last):
  File "/Users/samgupta/Github/control_loop/webapp/backend/../../src/resources/error_notification.py", line 17, in send_notification
    print(app.is_authenticated)
          ^^^^^^^^^^^^^^^^^^^^
  File "/Users/samgupta/Github/control_loop/control_loop/lib/python3.12/site-packages/chump/__init__.py", line 200, in is_authenticated
    self._authenticate()
  File "/Users/samgupta/Github/control_loop/control_loop/lib/python3.12/site-packages/chump/__init__.py", line 273, in _authenticate
    self._sounds = self._request('sound')[0]['sounds']
                   ^^^^^^^^^^^^^^^^^^^^^^
  File "/Users/samgupta/Github/control_loop/control_loop/lib/python3.12/site-packages/chump/__init__.py", line 334, in _request
    response = pool.open(url)
               ^^^^^^^^^^^^^^
  File "/Library/Frameworks/Python.framework/Versions/3.12/lib/python3.12/urllib/request.py", line 515, in open
    response = self._open(req, data)
               ^^^^^^^^^^^^^^^^^^^^^
  File "/Library/Frameworks/Python.framework/Versions/3.12/lib/python3.12/urllib/request.py", line 532, in _open
    result = self._call_chain(self.handle_open, protocol, protocol +
             ^^^^^^^^^^^^^^^^^^^^^^^^^^^^^^^^^^^^^^^^^^^^^^^^^^^^^^^
  File "/Library/Frameworks/Python.framework/Versions/3.12/lib/python3.12/urllib/request.py", line 492, in _call_chain
    result = func(*args)
             ^^^^^^^^^^^
  File "/Users/samgupta/Github/control_loop/control_loop/lib/python3.12/site-packages/chump/connection_pool.py", line 82, in https_open
    if response.raw.will_close:
       ^^^^^^^^^^^^
AttributeError: 'NoneType' object has no attribute 'raw'

2024-07-23 13:21:50 - ERROR - Backup Server Starting
2024-07-23 13:26:36 - ERROR - Error in handle_client
Unexpected error: sent 1001 (going away) Server shutdown; then received 1001 (going away) Server shutdown
Traceback (most recent call last):
  File "/Users/samgupta/Github/control_loop/webapp/backend/api_server.py", line 127, in handle_client
    message = await asyncio.wait_for(websocket.recv(), timeout=60)
              ^^^^^^^^^^^^^^^^^^^^^^^^^^^^^^^^^^^^^^^^^^^^^^^^^^^^
  File "/Library/Frameworks/Python.framework/Versions/3.12/lib/python3.12/asyncio/tasks.py", line 520, in wait_for
    return await fut
           ^^^^^^^^^
  File "/Users/samgupta/Github/control_loop/control_loop/lib/python3.12/site-packages/websockets/legacy/protocol.py", line 568, in recv
    await self.ensure_open()
  File "/Users/samgupta/Github/control_loop/control_loop/lib/python3.12/site-packages/websockets/legacy/protocol.py", line 948, in ensure_open
    raise self.connection_closed_exc()
websockets.exceptions.ConnectionClosedOK: sent 1001 (going away) Server shutdown; then received 1001 (going away) Server shutdown

2024-07-23 13:26:36 - ERROR - type of exception: <class 'websockets.exceptions.ConnectionClosedOK'>
2024-07-23 13:26:36 - ERROR - Error in send_notification: 'NoneType' object has no attribute 'raw'
Traceback (most recent call last):
  File "/Users/samgupta/Github/control_loop/webapp/backend/api_server.py", line 127, in handle_client
    message = await asyncio.wait_for(websocket.recv(), timeout=60)
              ^^^^^^^^^^^^^^^^^^^^^^^^^^^^^^^^^^^^^^^^^^^^^^^^^^^^
  File "/Library/Frameworks/Python.framework/Versions/3.12/lib/python3.12/asyncio/tasks.py", line 520, in wait_for
    return await fut
           ^^^^^^^^^
  File "/Users/samgupta/Github/control_loop/control_loop/lib/python3.12/site-packages/websockets/legacy/protocol.py", line 568, in recv
    await self.ensure_open()
  File "/Users/samgupta/Github/control_loop/control_loop/lib/python3.12/site-packages/websockets/legacy/protocol.py", line 948, in ensure_open
    raise self.connection_closed_exc()
websockets.exceptions.ConnectionClosedOK: sent 1001 (going away) Server shutdown; then received 1001 (going away) Server shutdown

During handling of the above exception, another exception occurred:

Traceback (most recent call last):
  File "/Users/samgupta/Github/control_loop/webapp/backend/../../src/resources/error_notification.py", line 17, in send_notification
    print(app.is_authenticated)
          ^^^^^^^^^^^^^^^^^^^^
  File "/Users/samgupta/Github/control_loop/control_loop/lib/python3.12/site-packages/chump/__init__.py", line 200, in is_authenticated
    self._authenticate()
  File "/Users/samgupta/Github/control_loop/control_loop/lib/python3.12/site-packages/chump/__init__.py", line 273, in _authenticate
    self._sounds = self._request('sound')[0]['sounds']
                   ^^^^^^^^^^^^^^^^^^^^^^
  File "/Users/samgupta/Github/control_loop/control_loop/lib/python3.12/site-packages/chump/__init__.py", line 334, in _request
    response = pool.open(url)
               ^^^^^^^^^^^^^^
  File "/Library/Frameworks/Python.framework/Versions/3.12/lib/python3.12/urllib/request.py", line 515, in open
    response = self._open(req, data)
               ^^^^^^^^^^^^^^^^^^^^^
  File "/Library/Frameworks/Python.framework/Versions/3.12/lib/python3.12/urllib/request.py", line 532, in _open
    result = self._call_chain(self.handle_open, protocol, protocol +
             ^^^^^^^^^^^^^^^^^^^^^^^^^^^^^^^^^^^^^^^^^^^^^^^^^^^^^^^
  File "/Library/Frameworks/Python.framework/Versions/3.12/lib/python3.12/urllib/request.py", line 492, in _call_chain
    result = func(*args)
             ^^^^^^^^^^^
  File "/Users/samgupta/Github/control_loop/control_loop/lib/python3.12/site-packages/chump/connection_pool.py", line 82, in https_open
    if response.raw.will_close:
       ^^^^^^^^^^^^
AttributeError: 'NoneType' object has no attribute 'raw'

2024-07-23 13:26:36 - ERROR - Backup Server Starting
2024-07-23 13:27:15 - ERROR - Error in handle_client
Unexpected error: sent 1001 (going away) Server shutdown; then received 1001 (going away) Server shutdown
Traceback (most recent call last):
  File "/Users/samgupta/Github/control_loop/webapp/backend/api_server.py", line 127, in handle_client
    message = await asyncio.wait_for(websocket.recv(), timeout=60)
              ^^^^^^^^^^^^^^^^^^^^^^^^^^^^^^^^^^^^^^^^^^^^^^^^^^^^
  File "/Library/Frameworks/Python.framework/Versions/3.12/lib/python3.12/asyncio/tasks.py", line 520, in wait_for
    return await fut
           ^^^^^^^^^
  File "/Users/samgupta/Github/control_loop/control_loop/lib/python3.12/site-packages/websockets/legacy/protocol.py", line 568, in recv
    await self.ensure_open()
  File "/Users/samgupta/Github/control_loop/control_loop/lib/python3.12/site-packages/websockets/legacy/protocol.py", line 948, in ensure_open
    raise self.connection_closed_exc()
websockets.exceptions.ConnectionClosedOK: sent 1001 (going away) Server shutdown; then received 1001 (going away) Server shutdown

2024-07-23 13:27:15 - ERROR - type of exception: <class 'websockets.exceptions.ConnectionClosedOK'>
2024-07-23 13:27:15 - ERROR - Error in send_notification: 'NoneType' object has no attribute 'raw'
Traceback (most recent call last):
  File "/Users/samgupta/Github/control_loop/webapp/backend/api_server.py", line 127, in handle_client
    message = await asyncio.wait_for(websocket.recv(), timeout=60)
              ^^^^^^^^^^^^^^^^^^^^^^^^^^^^^^^^^^^^^^^^^^^^^^^^^^^^
  File "/Library/Frameworks/Python.framework/Versions/3.12/lib/python3.12/asyncio/tasks.py", line 520, in wait_for
    return await fut
           ^^^^^^^^^
  File "/Users/samgupta/Github/control_loop/control_loop/lib/python3.12/site-packages/websockets/legacy/protocol.py", line 568, in recv
    await self.ensure_open()
  File "/Users/samgupta/Github/control_loop/control_loop/lib/python3.12/site-packages/websockets/legacy/protocol.py", line 948, in ensure_open
    raise self.connection_closed_exc()
websockets.exceptions.ConnectionClosedOK: sent 1001 (going away) Server shutdown; then received 1001 (going away) Server shutdown

During handling of the above exception, another exception occurred:

Traceback (most recent call last):
  File "/Users/samgupta/Github/control_loop/webapp/backend/../../src/resources/error_notification.py", line 17, in send_notification
    print(app.is_authenticated)
          ^^^^^^^^^^^^^^^^^^^^
  File "/Users/samgupta/Github/control_loop/control_loop/lib/python3.12/site-packages/chump/__init__.py", line 200, in is_authenticated
    self._authenticate()
  File "/Users/samgupta/Github/control_loop/control_loop/lib/python3.12/site-packages/chump/__init__.py", line 273, in _authenticate
    self._sounds = self._request('sound')[0]['sounds']
                   ^^^^^^^^^^^^^^^^^^^^^^
  File "/Users/samgupta/Github/control_loop/control_loop/lib/python3.12/site-packages/chump/__init__.py", line 334, in _request
    response = pool.open(url)
               ^^^^^^^^^^^^^^
  File "/Library/Frameworks/Python.framework/Versions/3.12/lib/python3.12/urllib/request.py", line 515, in open
    response = self._open(req, data)
               ^^^^^^^^^^^^^^^^^^^^^
  File "/Library/Frameworks/Python.framework/Versions/3.12/lib/python3.12/urllib/request.py", line 532, in _open
    result = self._call_chain(self.handle_open, protocol, protocol +
             ^^^^^^^^^^^^^^^^^^^^^^^^^^^^^^^^^^^^^^^^^^^^^^^^^^^^^^^
  File "/Library/Frameworks/Python.framework/Versions/3.12/lib/python3.12/urllib/request.py", line 492, in _call_chain
    result = func(*args)
             ^^^^^^^^^^^
  File "/Users/samgupta/Github/control_loop/control_loop/lib/python3.12/site-packages/chump/connection_pool.py", line 82, in https_open
    if response.raw.will_close:
       ^^^^^^^^^^^^
AttributeError: 'NoneType' object has no attribute 'raw'

2024-07-23 13:27:15 - ERROR - Backup Server Starting
2024-07-23 13:28:20 - ERROR - Error in send_config_data
Unexpected error: no close frame received or sent
Traceback (most recent call last):
  File "/Users/samgupta/Github/control_loop/webapp/backend/api_server.py", line 59, in send_config_data
    await websocket.send(json.dumps({
  File "/Users/samgupta/Github/control_loop/control_loop/lib/python3.12/site-packages/websockets/legacy/protocol.py", line 647, in send
    await self.write_frame(True, opcode, data)
  File "/Users/samgupta/Github/control_loop/control_loop/lib/python3.12/site-packages/websockets/legacy/protocol.py", line 1209, in write_frame
    await self.drain()
  File "/Users/samgupta/Github/control_loop/control_loop/lib/python3.12/site-packages/websockets/legacy/protocol.py", line 1198, in drain
    await self.ensure_open()
  File "/Users/samgupta/Github/control_loop/control_loop/lib/python3.12/site-packages/websockets/legacy/protocol.py", line 939, in ensure_open
    raise self.connection_closed_exc()
websockets.exceptions.ConnectionClosedError: no close frame received or sent

2024-07-23 13:28:20 - ERROR - type of exception: <class 'websockets.exceptions.ConnectionClosedError'>
2024-07-23 13:29:55 - ERROR - Error in handle_client
Unexpected error: sent 1001 (going away) Server shutdown; then received 1001 (going away) Server shutdown
Traceback (most recent call last):
  File "/Users/samgupta/Github/control_loop/webapp/backend/api_server.py", line 127, in handle_client
    message = await asyncio.wait_for(websocket.recv(), timeout=60)
              ^^^^^^^^^^^^^^^^^^^^^^^^^^^^^^^^^^^^^^^^^^^^^^^^^^^^
  File "/Library/Frameworks/Python.framework/Versions/3.12/lib/python3.12/asyncio/tasks.py", line 520, in wait_for
    return await fut
           ^^^^^^^^^
  File "/Users/samgupta/Github/control_loop/control_loop/lib/python3.12/site-packages/websockets/legacy/protocol.py", line 568, in recv
    await self.ensure_open()
  File "/Users/samgupta/Github/control_loop/control_loop/lib/python3.12/site-packages/websockets/legacy/protocol.py", line 948, in ensure_open
    raise self.connection_closed_exc()
websockets.exceptions.ConnectionClosedOK: sent 1001 (going away) Server shutdown; then received 1001 (going away) Server shutdown

2024-07-23 13:29:55 - ERROR - type of exception: <class 'websockets.exceptions.ConnectionClosedOK'>
2024-07-23 13:29:55 - ERROR - Error in send_notification: 'NoneType' object has no attribute 'raw'
Traceback (most recent call last):
  File "/Users/samgupta/Github/control_loop/webapp/backend/api_server.py", line 127, in handle_client
    message = await asyncio.wait_for(websocket.recv(), timeout=60)
              ^^^^^^^^^^^^^^^^^^^^^^^^^^^^^^^^^^^^^^^^^^^^^^^^^^^^
  File "/Library/Frameworks/Python.framework/Versions/3.12/lib/python3.12/asyncio/tasks.py", line 520, in wait_for
    return await fut
           ^^^^^^^^^
  File "/Users/samgupta/Github/control_loop/control_loop/lib/python3.12/site-packages/websockets/legacy/protocol.py", line 568, in recv
    await self.ensure_open()
  File "/Users/samgupta/Github/control_loop/control_loop/lib/python3.12/site-packages/websockets/legacy/protocol.py", line 948, in ensure_open
    raise self.connection_closed_exc()
websockets.exceptions.ConnectionClosedOK: sent 1001 (going away) Server shutdown; then received 1001 (going away) Server shutdown

During handling of the above exception, another exception occurred:

Traceback (most recent call last):
  File "/Users/samgupta/Github/control_loop/webapp/backend/../../src/resources/error_notification.py", line 17, in send_notification
    print(app.is_authenticated)
          ^^^^^^^^^^^^^^^^^^^^
  File "/Users/samgupta/Github/control_loop/control_loop/lib/python3.12/site-packages/chump/__init__.py", line 200, in is_authenticated
    self._authenticate()
  File "/Users/samgupta/Github/control_loop/control_loop/lib/python3.12/site-packages/chump/__init__.py", line 273, in _authenticate
    self._sounds = self._request('sound')[0]['sounds']
                   ^^^^^^^^^^^^^^^^^^^^^^
  File "/Users/samgupta/Github/control_loop/control_loop/lib/python3.12/site-packages/chump/__init__.py", line 334, in _request
    response = pool.open(url)
               ^^^^^^^^^^^^^^
  File "/Library/Frameworks/Python.framework/Versions/3.12/lib/python3.12/urllib/request.py", line 515, in open
    response = self._open(req, data)
               ^^^^^^^^^^^^^^^^^^^^^
  File "/Library/Frameworks/Python.framework/Versions/3.12/lib/python3.12/urllib/request.py", line 532, in _open
    result = self._call_chain(self.handle_open, protocol, protocol +
             ^^^^^^^^^^^^^^^^^^^^^^^^^^^^^^^^^^^^^^^^^^^^^^^^^^^^^^^
  File "/Library/Frameworks/Python.framework/Versions/3.12/lib/python3.12/urllib/request.py", line 492, in _call_chain
    result = func(*args)
             ^^^^^^^^^^^
  File "/Users/samgupta/Github/control_loop/control_loop/lib/python3.12/site-packages/chump/connection_pool.py", line 82, in https_open
    if response.raw.will_close:
       ^^^^^^^^^^^^
AttributeError: 'NoneType' object has no attribute 'raw'

2024-07-23 13:29:55 - ERROR - Backup Server Starting
2024-07-23 13:31:50 - ERROR - Error in handle_client
Unexpected error: sent 1001 (going away) Server shutdown; then received 1001 (going away) Server shutdown
Traceback (most recent call last):
  File "/Users/samgupta/Github/control_loop/webapp/backend/api_server.py", line 127, in handle_client
    message = await asyncio.wait_for(websocket.recv(), timeout=60)
              ^^^^^^^^^^^^^^^^^^^^^^^^^^^^^^^^^^^^^^^^^^^^^^^^^^^^
  File "/Library/Frameworks/Python.framework/Versions/3.12/lib/python3.12/asyncio/tasks.py", line 520, in wait_for
    return await fut
           ^^^^^^^^^
  File "/Users/samgupta/Github/control_loop/control_loop/lib/python3.12/site-packages/websockets/legacy/protocol.py", line 568, in recv
    await self.ensure_open()
  File "/Users/samgupta/Github/control_loop/control_loop/lib/python3.12/site-packages/websockets/legacy/protocol.py", line 948, in ensure_open
    raise self.connection_closed_exc()
websockets.exceptions.ConnectionClosedOK: sent 1001 (going away) Server shutdown; then received 1001 (going away) Server shutdown

2024-07-23 13:31:50 - ERROR - type of exception: <class 'websockets.exceptions.ConnectionClosedOK'>
2024-07-23 13:31:50 - ERROR - Error in send_notification: 'NoneType' object has no attribute 'raw'
Traceback (most recent call last):
  File "/Users/samgupta/Github/control_loop/webapp/backend/api_server.py", line 127, in handle_client
    message = await asyncio.wait_for(websocket.recv(), timeout=60)
              ^^^^^^^^^^^^^^^^^^^^^^^^^^^^^^^^^^^^^^^^^^^^^^^^^^^^
  File "/Library/Frameworks/Python.framework/Versions/3.12/lib/python3.12/asyncio/tasks.py", line 520, in wait_for
    return await fut
           ^^^^^^^^^
  File "/Users/samgupta/Github/control_loop/control_loop/lib/python3.12/site-packages/websockets/legacy/protocol.py", line 568, in recv
    await self.ensure_open()
  File "/Users/samgupta/Github/control_loop/control_loop/lib/python3.12/site-packages/websockets/legacy/protocol.py", line 948, in ensure_open
    raise self.connection_closed_exc()
websockets.exceptions.ConnectionClosedOK: sent 1001 (going away) Server shutdown; then received 1001 (going away) Server shutdown

During handling of the above exception, another exception occurred:

Traceback (most recent call last):
  File "/Users/samgupta/Github/control_loop/webapp/backend/../../src/resources/error_notification.py", line 17, in send_notification
    print(app.is_authenticated)
          ^^^^^^^^^^^^^^^^^^^^
  File "/Users/samgupta/Github/control_loop/control_loop/lib/python3.12/site-packages/chump/__init__.py", line 200, in is_authenticated
    self._authenticate()
  File "/Users/samgupta/Github/control_loop/control_loop/lib/python3.12/site-packages/chump/__init__.py", line 273, in _authenticate
    self._sounds = self._request('sound')[0]['sounds']
                   ^^^^^^^^^^^^^^^^^^^^^^
  File "/Users/samgupta/Github/control_loop/control_loop/lib/python3.12/site-packages/chump/__init__.py", line 334, in _request
    response = pool.open(url)
               ^^^^^^^^^^^^^^
  File "/Library/Frameworks/Python.framework/Versions/3.12/lib/python3.12/urllib/request.py", line 515, in open
    response = self._open(req, data)
               ^^^^^^^^^^^^^^^^^^^^^
  File "/Library/Frameworks/Python.framework/Versions/3.12/lib/python3.12/urllib/request.py", line 532, in _open
    result = self._call_chain(self.handle_open, protocol, protocol +
             ^^^^^^^^^^^^^^^^^^^^^^^^^^^^^^^^^^^^^^^^^^^^^^^^^^^^^^^
  File "/Library/Frameworks/Python.framework/Versions/3.12/lib/python3.12/urllib/request.py", line 492, in _call_chain
    result = func(*args)
             ^^^^^^^^^^^
  File "/Users/samgupta/Github/control_loop/control_loop/lib/python3.12/site-packages/chump/connection_pool.py", line 82, in https_open
    if response.raw.will_close:
       ^^^^^^^^^^^^
AttributeError: 'NoneType' object has no attribute 'raw'

2024-07-23 13:31:50 - ERROR - Backup Server Starting
2024-07-23 13:31:50 - ERROR - Error in get_controller: 
 Input: fermentation_loop, 
 [Errno 51] Network is unreachable
Traceback (most recent call last):
  File "/Users/samgupta/Github/control_loop/webapp/backend/api_server.py", line 127, in handle_client
    message = await asyncio.wait_for(websocket.recv(), timeout=60)
              ^^^^^^^^^^^^^^^^^^^^^^^^^^^^^^^^^^^^^^^^^^^^^^^^^^^^
  File "/Library/Frameworks/Python.framework/Versions/3.12/lib/python3.12/asyncio/tasks.py", line 520, in wait_for
    return await fut
           ^^^^^^^^^
  File "/Users/samgupta/Github/control_loop/control_loop/lib/python3.12/site-packages/websockets/legacy/protocol.py", line 568, in recv
    await self.ensure_open()
  File "/Users/samgupta/Github/control_loop/control_loop/lib/python3.12/site-packages/websockets/legacy/protocol.py", line 948, in ensure_open
    raise self.connection_closed_exc()
websockets.exceptions.ConnectionClosedOK: sent 1001 (going away) Server shutdown; then received 1001 (going away) Server shutdown

During handling of the above exception, another exception occurred:

Traceback (most recent call last):
  File "/Users/samgupta/Github/control_loop/webapp/backend/manager_server.py", line 266, in get_controller
    controller = c.create_controller(loop_id)
                 ^^^^^^^^^^^^^^^^^^^^^^^^^^^^
  File "/Users/samgupta/Github/control_loop/webapp/backend/../../src/controllers_mqtt.py", line 41, in create_controller
    controller = FermentationController()
                 ^^^^^^^^^^^^^^^^^^^^^^^^
  File "/Users/samgupta/Github/control_loop/webapp/backend/../../src/controllers_mqtt.py", line 529, in __init__
    self.mqtt_client = ControllerMQTTClient(broker_address="192.168.0.25")
                       ^^^^^^^^^^^^^^^^^^^^^^^^^^^^^^^^^^^^^^^^^^^^^^^^^^^
  File "/Users/samgupta/Github/control_loop/webapp/backend/../../src/controller_mqtt_client.py", line 12, in __init__
    self.client.connect(broker_address, 1883, 60)
  File "/Users/samgupta/Github/control_loop/control_loop/lib/python3.12/site-packages/paho/mqtt/client.py", line 1435, in connect
    return self.reconnect()
           ^^^^^^^^^^^^^^^^
  File "/Users/samgupta/Github/control_loop/control_loop/lib/python3.12/site-packages/paho/mqtt/client.py", line 1598, in reconnect
    self._sock = self._create_socket()
                 ^^^^^^^^^^^^^^^^^^^^^
  File "/Users/samgupta/Github/control_loop/control_loop/lib/python3.12/site-packages/paho/mqtt/client.py", line 4609, in _create_socket
    sock = self._create_socket_connection()
           ^^^^^^^^^^^^^^^^^^^^^^^^^^^^^^^^
  File "/Users/samgupta/Github/control_loop/control_loop/lib/python3.12/site-packages/paho/mqtt/client.py", line 4640, in _create_socket_connection
    return socket.create_connection(addr, timeout=self._connect_timeout, source_address=source)
           ^^^^^^^^^^^^^^^^^^^^^^^^^^^^^^^^^^^^^^^^^^^^^^^^^^^^^^^^^^^^^^^^^^^^^^^^^^^^^^^^^^^^
  File "/Library/Frameworks/Python.framework/Versions/3.12/lib/python3.12/socket.py", line 853, in create_connection
    raise exceptions[0]
  File "/Library/Frameworks/Python.framework/Versions/3.12/lib/python3.12/socket.py", line 838, in create_connection
    sock.connect(sa)
OSError: [Errno 51] Network is unreachable

2024-07-23 13:31:50 - ERROR - Error in handle_server_error
Unexpected error: argument of type 'NoneType' is not iterable
Traceback (most recent call last):
  File "/Users/samgupta/Github/control_loop/webapp/backend/api_server.py", line 127, in handle_client
    message = await asyncio.wait_for(websocket.recv(), timeout=60)
              ^^^^^^^^^^^^^^^^^^^^^^^^^^^^^^^^^^^^^^^^^^^^^^^^^^^^
  File "/Library/Frameworks/Python.framework/Versions/3.12/lib/python3.12/asyncio/tasks.py", line 520, in wait_for
    return await fut
           ^^^^^^^^^
  File "/Users/samgupta/Github/control_loop/control_loop/lib/python3.12/site-packages/websockets/legacy/protocol.py", line 568, in recv
    await self.ensure_open()
  File "/Users/samgupta/Github/control_loop/control_loop/lib/python3.12/site-packages/websockets/legacy/protocol.py", line 948, in ensure_open
    raise self.connection_closed_exc()
websockets.exceptions.ConnectionClosedOK: sent 1001 (going away) Server shutdown; then received 1001 (going away) Server shutdown

During handling of the above exception, another exception occurred:

Traceback (most recent call last):
  File "/Users/samgupta/Github/control_loop/webapp/backend/api_server.py", line 229, in handle_server_error
    controller = await manager_server.stop_all(loop_id)
                 ^^^^^^^^^^^^^^^^^^^^^^^^^^^^^^^^^^^^^^
  File "/Users/samgupta/Github/control_loop/webapp/backend/manager_server.py", line 189, in stop_all
    if "control_task" in controller_info:
       ^^^^^^^^^^^^^^^^^^^^^^^^^^^^^^^^^
TypeError: argument of type 'NoneType' is not iterable

2024-07-23 13:31:50 - ERROR - type of exception: <class 'TypeError'>
2024-07-23 13:31:50 - ERROR - Error in send_notification: 'NoneType' object has no attribute 'raw'
Traceback (most recent call last):
  File "/Users/samgupta/Github/control_loop/webapp/backend/api_server.py", line 127, in handle_client
    message = await asyncio.wait_for(websocket.recv(), timeout=60)
              ^^^^^^^^^^^^^^^^^^^^^^^^^^^^^^^^^^^^^^^^^^^^^^^^^^^^
  File "/Library/Frameworks/Python.framework/Versions/3.12/lib/python3.12/asyncio/tasks.py", line 520, in wait_for
    return await fut
           ^^^^^^^^^
  File "/Users/samgupta/Github/control_loop/control_loop/lib/python3.12/site-packages/websockets/legacy/protocol.py", line 568, in recv
    await self.ensure_open()
  File "/Users/samgupta/Github/control_loop/control_loop/lib/python3.12/site-packages/websockets/legacy/protocol.py", line 948, in ensure_open
    raise self.connection_closed_exc()
websockets.exceptions.ConnectionClosedOK: sent 1001 (going away) Server shutdown; then received 1001 (going away) Server shutdown

During handling of the above exception, another exception occurred:

Traceback (most recent call last):
  File "/Users/samgupta/Github/control_loop/webapp/backend/api_server.py", line 229, in handle_server_error
    controller = await manager_server.stop_all(loop_id)
                 ^^^^^^^^^^^^^^^^^^^^^^^^^^^^^^^^^^^^^^
  File "/Users/samgupta/Github/control_loop/webapp/backend/manager_server.py", line 189, in stop_all
    if "control_task" in controller_info:
       ^^^^^^^^^^^^^^^^^^^^^^^^^^^^^^^^^
TypeError: argument of type 'NoneType' is not iterable

During handling of the above exception, another exception occurred:

Traceback (most recent call last):
  File "/Users/samgupta/Github/control_loop/webapp/backend/../../src/resources/error_notification.py", line 17, in send_notification
    print(app.is_authenticated)
          ^^^^^^^^^^^^^^^^^^^^
  File "/Users/samgupta/Github/control_loop/control_loop/lib/python3.12/site-packages/chump/__init__.py", line 200, in is_authenticated
    self._authenticate()
  File "/Users/samgupta/Github/control_loop/control_loop/lib/python3.12/site-packages/chump/__init__.py", line 273, in _authenticate
    self._sounds = self._request('sound')[0]['sounds']
                   ^^^^^^^^^^^^^^^^^^^^^^
  File "/Users/samgupta/Github/control_loop/control_loop/lib/python3.12/site-packages/chump/__init__.py", line 334, in _request
    response = pool.open(url)
               ^^^^^^^^^^^^^^
  File "/Library/Frameworks/Python.framework/Versions/3.12/lib/python3.12/urllib/request.py", line 515, in open
    response = self._open(req, data)
               ^^^^^^^^^^^^^^^^^^^^^
  File "/Library/Frameworks/Python.framework/Versions/3.12/lib/python3.12/urllib/request.py", line 532, in _open
    result = self._call_chain(self.handle_open, protocol, protocol +
             ^^^^^^^^^^^^^^^^^^^^^^^^^^^^^^^^^^^^^^^^^^^^^^^^^^^^^^^
  File "/Library/Frameworks/Python.framework/Versions/3.12/lib/python3.12/urllib/request.py", line 492, in _call_chain
    result = func(*args)
             ^^^^^^^^^^^
  File "/Users/samgupta/Github/control_loop/control_loop/lib/python3.12/site-packages/chump/connection_pool.py", line 82, in https_open
    if response.raw.will_close:
       ^^^^^^^^^^^^
AttributeError: 'NoneType' object has no attribute 'raw'

