2024-06-26 11:41:28 - ERROR - Error in handle_client
Unexpected error: received 1001 (going away); then sent 1001 (going away)
Traceback (most recent call last):
  File "/Users/mba_sam/Github/Nyoka Design Labs/control_loop/webapp/backend/api_server.py", line 47, in handle_client
    message = await asyncio.wait_for(websocket.recv(), timeout=60)
              ^^^^^^^^^^^^^^^^^^^^^^^^^^^^^^^^^^^^^^^^^^^^^^^^^^^^
  File "/Users/mba_sam/anaconda3/lib/python3.11/asyncio/tasks.py", line 489, in wait_for
    return fut.result()
           ^^^^^^^^^^^^
  File "/Users/mba_sam/Github/Nyoka Design Labs/control_loop/control_loop/lib/python3.11/site-packages/websockets/legacy/protocol.py", line 568, in recv
    await self.ensure_open()
  File "/Users/mba_sam/Github/Nyoka Design Labs/control_loop/control_loop/lib/python3.11/site-packages/websockets/legacy/protocol.py", line 939, in ensure_open
    raise self.connection_closed_exc()
websockets.exceptions.ConnectionClosedOK: received 1001 (going away); then sent 1001 (going away)

2024-06-26 11:43:10 - ERROR - Error in handle_client
Unexpected error: received 1001 (going away); then sent 1001 (going away)
Traceback (most recent call last):
  File "/Users/mba_sam/Github/Nyoka Design Labs/control_loop/webapp/backend/api_server.py", line 47, in handle_client
    message = await asyncio.wait_for(websocket.recv(), timeout=60)
              ^^^^^^^^^^^^^^^^^^^^^^^^^^^^^^^^^^^^^^^^^^^^^^^^^^^^
  File "/Users/mba_sam/anaconda3/lib/python3.11/asyncio/tasks.py", line 489, in wait_for
    return fut.result()
           ^^^^^^^^^^^^
  File "/Users/mba_sam/Github/Nyoka Design Labs/control_loop/control_loop/lib/python3.11/site-packages/websockets/legacy/protocol.py", line 568, in recv
    await self.ensure_open()
  File "/Users/mba_sam/Github/Nyoka Design Labs/control_loop/control_loop/lib/python3.11/site-packages/websockets/legacy/protocol.py", line 939, in ensure_open
    raise self.connection_closed_exc()
websockets.exceptions.ConnectionClosedOK: received 1001 (going away); then sent 1001 (going away)

2024-06-26 11:44:48 - ERROR - Error in send_status_update: 
 Input: {'type': 'status', 'loopID': 'fermentation_loop', 'control_loop_status': 'control_off', 'data_collection_status': 'data_collection_off', 'feed_pump_status': '0', 'lactose_pump_status': '4', 'base_pump_status': '2', 'feed_const_pump_status': '10', 'lactose_const_pump_status': '12', 'acid_pump_status': '14'}, 
 no close frame received or sent
Traceback (most recent call last):
  File "/Users/mba_sam/anaconda3/lib/python3.11/asyncio/runners.py", line 118, in run
    return self._loop.run_until_complete(task)
           ^^^^^^^^^^^^^^^^^^^^^^^^^^^^^^^^^^^
  File "/Users/mba_sam/anaconda3/lib/python3.11/asyncio/base_events.py", line 653, in run_until_complete
    return future.result()
           ^^^^^^^^^^^^^^^
  File "/Users/mba_sam/Github/Nyoka Design Labs/control_loop/webapp/backend/api_server.py", line 137, in main
    await start_server()
  File "/Users/mba_sam/Github/Nyoka Design Labs/control_loop/webapp/backend/api_server.py", line 99, in start_server
    await server.wait_closed()
  File "/Users/mba_sam/Github/Nyoka Design Labs/control_loop/control_loop/lib/python3.11/site-packages/websockets/legacy/server.py", line 814, in wait_closed
    await asyncio.shield(self.closed_waiter)
asyncio.exceptions.CancelledError

During handling of the above exception, another exception occurred:

Traceback (most recent call last):
  File "/Users/mba_sam/anaconda3/lib/python3.11/asyncio/runners.py", line 190, in run
    return runner.run(main)
           ^^^^^^^^^^^^^^^^
  File "/Users/mba_sam/anaconda3/lib/python3.11/asyncio/runners.py", line 123, in run
    raise KeyboardInterrupt()
KeyboardInterrupt

During handling of the above exception, another exception occurred:

Traceback (most recent call last):
  File "/Users/mba_sam/Github/Nyoka Design Labs/control_loop/control_loop/lib/python3.11/site-packages/websockets/legacy/protocol.py", line 1301, in close_connection
    await self.transfer_data_task
  File "/Users/mba_sam/Github/Nyoka Design Labs/control_loop/control_loop/lib/python3.11/site-packages/websockets/legacy/protocol.py", line 963, in transfer_data
    message = await self.read_message()
              ^^^^^^^^^^^^^^^^^^^^^^^^^
  File "/Users/mba_sam/Github/Nyoka Design Labs/control_loop/control_loop/lib/python3.11/site-packages/websockets/legacy/protocol.py", line 1033, in read_message
    frame = await self.read_data_frame(max_size=self.max_size)
            ^^^^^^^^^^^^^^^^^^^^^^^^^^^^^^^^^^^^^^^^^^^^^^^^^^
  File "/Users/mba_sam/Github/Nyoka Design Labs/control_loop/control_loop/lib/python3.11/site-packages/websockets/legacy/protocol.py", line 1108, in read_data_frame
    frame = await self.read_frame(max_size)
            ^^^^^^^^^^^^^^^^^^^^^^^^^^^^^^^
  File "/Users/mba_sam/Github/Nyoka Design Labs/control_loop/control_loop/lib/python3.11/site-packages/websockets/legacy/protocol.py", line 1165, in read_frame
    frame = await Frame.read(
            ^^^^^^^^^^^^^^^^^
  File "/Users/mba_sam/Github/Nyoka Design Labs/control_loop/control_loop/lib/python3.11/site-packages/websockets/legacy/framing.py", line 68, in read
    data = await reader(2)
           ^^^^^^^^^^^^^^^
  File "/Users/mba_sam/anaconda3/lib/python3.11/asyncio/streams.py", line 747, in readexactly
    await self._wait_for_data('readexactly')
  File "/Users/mba_sam/anaconda3/lib/python3.11/asyncio/streams.py", line 540, in _wait_for_data
    await self._waiter
asyncio.exceptions.CancelledError

The above exception was the direct cause of the following exception:

Traceback (most recent call last):
  File "/Users/mba_sam/Github/Nyoka Design Labs/control_loop/webapp/backend/manager_server.py", line 134, in send_status_update
    await websocket.send(json.dumps({"type": "status", **status}))
  File "/Users/mba_sam/Github/Nyoka Design Labs/control_loop/control_loop/lib/python3.11/site-packages/websockets/legacy/protocol.py", line 635, in send
    await self.ensure_open()
  File "/Users/mba_sam/Github/Nyoka Design Labs/control_loop/control_loop/lib/python3.11/site-packages/websockets/legacy/protocol.py", line 934, in ensure_open
    raise self.connection_closed_exc()
websockets.exceptions.ConnectionClosedError: no close frame received or sent

