2024-07-11 16:07:38 - ERROR - Error in handle_client
Unexpected error: received 1001 (going away); then sent 1001 (going away)
Traceback (most recent call last):
  File "/Users/samgupta/Github/control_loop/webapp/backend/api_server.py", line 53, in handle_client
    message = await asyncio.wait_for(websocket.recv(), timeout=60)
              ^^^^^^^^^^^^^^^^^^^^^^^^^^^^^^^^^^^^^^^^^^^^^^^^^^^^
  File "/Library/Frameworks/Python.framework/Versions/3.12/lib/python3.12/asyncio/tasks.py", line 520, in wait_for
    return await fut
           ^^^^^^^^^
  File "/Users/samgupta/Github/control_loop/control_loop/lib/python3.12/site-packages/websockets/legacy/protocol.py", line 568, in recv
    await self.ensure_open()
  File "/Users/samgupta/Github/control_loop/control_loop/lib/python3.12/site-packages/websockets/legacy/protocol.py", line 939, in ensure_open
    raise self.connection_closed_exc()
websockets.exceptions.ConnectionClosedOK: received 1001 (going away); then sent 1001 (going away)

2024-07-11 16:07:38 - ERROR - Error in handle_client
Unexpected error: received 1001 (going away); then sent 1001 (going away)
Traceback (most recent call last):
  File "/Users/samgupta/Github/control_loop/webapp/backend/api_server.py", line 53, in handle_client
    message = await asyncio.wait_for(websocket.recv(), timeout=60)
              ^^^^^^^^^^^^^^^^^^^^^^^^^^^^^^^^^^^^^^^^^^^^^^^^^^^^
  File "/Library/Frameworks/Python.framework/Versions/3.12/lib/python3.12/asyncio/tasks.py", line 520, in wait_for
    return await fut
           ^^^^^^^^^
  File "/Users/samgupta/Github/control_loop/control_loop/lib/python3.12/site-packages/websockets/legacy/protocol.py", line 568, in recv
    await self.ensure_open()
  File "/Users/samgupta/Github/control_loop/control_loop/lib/python3.12/site-packages/websockets/legacy/protocol.py", line 939, in ensure_open
    raise self.connection_closed_exc()
websockets.exceptions.ConnectionClosedOK: received 1001 (going away); then sent 1001 (going away)

2024-07-11 16:07:38 - ERROR - Error in send_notification: 'NoneType' object has no attribute 'raw'
Traceback (most recent call last):
  File "/Users/samgupta/Github/control_loop/webapp/backend/api_server.py", line 53, in handle_client
    message = await asyncio.wait_for(websocket.recv(), timeout=60)
              ^^^^^^^^^^^^^^^^^^^^^^^^^^^^^^^^^^^^^^^^^^^^^^^^^^^^
  File "/Library/Frameworks/Python.framework/Versions/3.12/lib/python3.12/asyncio/tasks.py", line 520, in wait_for
    return await fut
           ^^^^^^^^^
  File "/Users/samgupta/Github/control_loop/control_loop/lib/python3.12/site-packages/websockets/legacy/protocol.py", line 568, in recv
    await self.ensure_open()
  File "/Users/samgupta/Github/control_loop/control_loop/lib/python3.12/site-packages/websockets/legacy/protocol.py", line 939, in ensure_open
    raise self.connection_closed_exc()
websockets.exceptions.ConnectionClosedOK: received 1001 (going away); then sent 1001 (going away)

During handling of the above exception, another exception occurred:

Traceback (most recent call last):
  File "/Users/samgupta/Github/control_loop/webapp/backend/../../src/resources/error_notification.py", line 12, in send_notification
    print(user.is_authenticated, user.devices)
          ^^^^^^^^^^^^^^^^^^^^^
  File "/Users/samgupta/Github/control_loop/control_loop/lib/python3.12/site-packages/chump/__init__.py", line 400, in is_authenticated
    self._authenticate()
  File "/Users/samgupta/Github/control_loop/control_loop/lib/python3.12/site-packages/chump/__init__.py", line 469, in _authenticate
    response, _ = self.app._request('validate', {'user': self.token})
                  ^^^^^^^^^^^^^^^^^^^^^^^^^^^^^^^^^^^^^^^^^^^^^^^^^^^
  File "/Users/samgupta/Github/control_loop/control_loop/lib/python3.12/site-packages/chump/__init__.py", line 337, in _request
    response = pool.open(url, bytes(urlencode(data), 'utf-8', 'strict') if data else None)
               ^^^^^^^^^^^^^^^^^^^^^^^^^^^^^^^^^^^^^^^^^^^^^^^^^^^^^^^^^^^^^^^^^^^^^^^^^^^
  File "/Library/Frameworks/Python.framework/Versions/3.12/lib/python3.12/urllib/request.py", line 515, in open
    response = self._open(req, data)
               ^^^^^^^^^^^^^^^^^^^^^
  File "/Library/Frameworks/Python.framework/Versions/3.12/lib/python3.12/urllib/request.py", line 532, in _open
    result = self._call_chain(self.handle_open, protocol, protocol +
             ^^^^^^^^^^^^^^^^^^^^^^^^^^^^^^^^^^^^^^^^^^^^^^^^^^^^^^^
  File "/Library/Frameworks/Python.framework/Versions/3.12/lib/python3.12/urllib/request.py", line 492, in _call_chain
    result = func(*args)
             ^^^^^^^^^^^
  File "/Users/samgupta/Github/control_loop/control_loop/lib/python3.12/site-packages/chump/connection_pool.py", line 82, in https_open
    if response.raw.will_close:
       ^^^^^^^^^^^^
AttributeError: 'NoneType' object has no attribute 'raw'

2024-07-11 16:07:38 - ERROR - Backup Server Starting
2024-07-11 16:07:43 - ERROR - Error in get_controller: 
 Input: fermentation_loop, 
 timed out
Traceback (most recent call last):
  File "/Users/samgupta/Github/control_loop/webapp/backend/api_server.py", line 53, in handle_client
    message = await asyncio.wait_for(websocket.recv(), timeout=60)
              ^^^^^^^^^^^^^^^^^^^^^^^^^^^^^^^^^^^^^^^^^^^^^^^^^^^^
  File "/Library/Frameworks/Python.framework/Versions/3.12/lib/python3.12/asyncio/tasks.py", line 520, in wait_for
    return await fut
           ^^^^^^^^^
  File "/Users/samgupta/Github/control_loop/control_loop/lib/python3.12/site-packages/websockets/legacy/protocol.py", line 568, in recv
    await self.ensure_open()
  File "/Users/samgupta/Github/control_loop/control_loop/lib/python3.12/site-packages/websockets/legacy/protocol.py", line 939, in ensure_open
    raise self.connection_closed_exc()
websockets.exceptions.ConnectionClosedOK: received 1001 (going away); then sent 1001 (going away)

During handling of the above exception, another exception occurred:

Traceback (most recent call last):
  File "/Users/samgupta/Github/control_loop/webapp/backend/manager_server.py", line 270, in get_controller
    controller = c.create_controller(loop_id)
                 ^^^^^^^^^^^^^^^^^^^^^^^^^^^^
  File "/Users/samgupta/Github/control_loop/webapp/backend/../../src/controllers_mqtt.py", line 41, in create_controller
    controller = FermentationController()
                 ^^^^^^^^^^^^^^^^^^^^^^^^
  File "/Users/samgupta/Github/control_loop/webapp/backend/../../src/controllers_mqtt.py", line 518, in __init__
    self.mqtt_client = ControllerMQTTClient(broker_address="192.168.0.25")
                       ^^^^^^^^^^^^^^^^^^^^^^^^^^^^^^^^^^^^^^^^^^^^^^^^^^^
  File "/Users/samgupta/Github/control_loop/webapp/backend/../../src/controller_mqtt_client.py", line 9, in __init__
    self.client.connect(broker_address, 1883, 60)
  File "/Users/samgupta/Github/control_loop/control_loop/lib/python3.12/site-packages/paho/mqtt/client.py", line 1435, in connect
    return self.reconnect()
           ^^^^^^^^^^^^^^^^
  File "/Users/samgupta/Github/control_loop/control_loop/lib/python3.12/site-packages/paho/mqtt/client.py", line 1598, in reconnect
    self._sock = self._create_socket()
                 ^^^^^^^^^^^^^^^^^^^^^
  File "/Users/samgupta/Github/control_loop/control_loop/lib/python3.12/site-packages/paho/mqtt/client.py", line 4609, in _create_socket
    sock = self._create_socket_connection()
           ^^^^^^^^^^^^^^^^^^^^^^^^^^^^^^^^
  File "/Users/samgupta/Github/control_loop/control_loop/lib/python3.12/site-packages/paho/mqtt/client.py", line 4640, in _create_socket_connection
    return socket.create_connection(addr, timeout=self._connect_timeout, source_address=source)
           ^^^^^^^^^^^^^^^^^^^^^^^^^^^^^^^^^^^^^^^^^^^^^^^^^^^^^^^^^^^^^^^^^^^^^^^^^^^^^^^^^^^^
  File "/Library/Frameworks/Python.framework/Versions/3.12/lib/python3.12/socket.py", line 853, in create_connection
    raise exceptions[0]
  File "/Library/Frameworks/Python.framework/Versions/3.12/lib/python3.12/socket.py", line 838, in create_connection
    sock.connect(sa)
TimeoutError: timed out

2024-07-11 16:07:43 - ERROR - Error in handle_server_error
Unexpected error: argument of type 'NoneType' is not iterable
Traceback (most recent call last):
  File "/Users/samgupta/Github/control_loop/webapp/backend/api_server.py", line 53, in handle_client
    message = await asyncio.wait_for(websocket.recv(), timeout=60)
              ^^^^^^^^^^^^^^^^^^^^^^^^^^^^^^^^^^^^^^^^^^^^^^^^^^^^
  File "/Library/Frameworks/Python.framework/Versions/3.12/lib/python3.12/asyncio/tasks.py", line 520, in wait_for
    return await fut
           ^^^^^^^^^
  File "/Users/samgupta/Github/control_loop/control_loop/lib/python3.12/site-packages/websockets/legacy/protocol.py", line 568, in recv
    await self.ensure_open()
  File "/Users/samgupta/Github/control_loop/control_loop/lib/python3.12/site-packages/websockets/legacy/protocol.py", line 939, in ensure_open
    raise self.connection_closed_exc()
websockets.exceptions.ConnectionClosedOK: received 1001 (going away); then sent 1001 (going away)

During handling of the above exception, another exception occurred:

Traceback (most recent call last):
  File "/Users/samgupta/Github/control_loop/webapp/backend/api_server.py", line 144, in handle_server_error
    controller = await manager_server.stop_all(loop_id)
                 ^^^^^^^^^^^^^^^^^^^^^^^^^^^^^^^^^^^^^^
  File "/Users/samgupta/Github/control_loop/webapp/backend/manager_server.py", line 191, in stop_all
    if "control_task" in controller_info:
       ^^^^^^^^^^^^^^^^^^^^^^^^^^^^^^^^^
TypeError: argument of type 'NoneType' is not iterable

2024-07-11 16:07:43 - ERROR - Error in send_notification: 'NoneType' object has no attribute 'raw'
Traceback (most recent call last):
  File "/Users/samgupta/Github/control_loop/webapp/backend/api_server.py", line 53, in handle_client
    message = await asyncio.wait_for(websocket.recv(), timeout=60)
              ^^^^^^^^^^^^^^^^^^^^^^^^^^^^^^^^^^^^^^^^^^^^^^^^^^^^
  File "/Library/Frameworks/Python.framework/Versions/3.12/lib/python3.12/asyncio/tasks.py", line 520, in wait_for
    return await fut
           ^^^^^^^^^
  File "/Users/samgupta/Github/control_loop/control_loop/lib/python3.12/site-packages/websockets/legacy/protocol.py", line 568, in recv
    await self.ensure_open()
  File "/Users/samgupta/Github/control_loop/control_loop/lib/python3.12/site-packages/websockets/legacy/protocol.py", line 939, in ensure_open
    raise self.connection_closed_exc()
websockets.exceptions.ConnectionClosedOK: received 1001 (going away); then sent 1001 (going away)

During handling of the above exception, another exception occurred:

Traceback (most recent call last):
  File "/Users/samgupta/Github/control_loop/webapp/backend/api_server.py", line 144, in handle_server_error
    controller = await manager_server.stop_all(loop_id)
                 ^^^^^^^^^^^^^^^^^^^^^^^^^^^^^^^^^^^^^^
  File "/Users/samgupta/Github/control_loop/webapp/backend/manager_server.py", line 191, in stop_all
    if "control_task" in controller_info:
       ^^^^^^^^^^^^^^^^^^^^^^^^^^^^^^^^^
TypeError: argument of type 'NoneType' is not iterable

During handling of the above exception, another exception occurred:

Traceback (most recent call last):
  File "/Users/samgupta/Github/control_loop/webapp/backend/../../src/resources/error_notification.py", line 12, in send_notification
    print(user.is_authenticated, user.devices)
          ^^^^^^^^^^^^^^^^^^^^^
  File "/Users/samgupta/Github/control_loop/control_loop/lib/python3.12/site-packages/chump/__init__.py", line 400, in is_authenticated
    self._authenticate()
  File "/Users/samgupta/Github/control_loop/control_loop/lib/python3.12/site-packages/chump/__init__.py", line 469, in _authenticate
    response, _ = self.app._request('validate', {'user': self.token})
                  ^^^^^^^^^^^^^^^^^^^^^^^^^^^^^^^^^^^^^^^^^^^^^^^^^^^
  File "/Users/samgupta/Github/control_loop/control_loop/lib/python3.12/site-packages/chump/__init__.py", line 337, in _request
    response = pool.open(url, bytes(urlencode(data), 'utf-8', 'strict') if data else None)
               ^^^^^^^^^^^^^^^^^^^^^^^^^^^^^^^^^^^^^^^^^^^^^^^^^^^^^^^^^^^^^^^^^^^^^^^^^^^
  File "/Library/Frameworks/Python.framework/Versions/3.12/lib/python3.12/urllib/request.py", line 515, in open
    response = self._open(req, data)
               ^^^^^^^^^^^^^^^^^^^^^
  File "/Library/Frameworks/Python.framework/Versions/3.12/lib/python3.12/urllib/request.py", line 532, in _open
    result = self._call_chain(self.handle_open, protocol, protocol +
             ^^^^^^^^^^^^^^^^^^^^^^^^^^^^^^^^^^^^^^^^^^^^^^^^^^^^^^^
  File "/Library/Frameworks/Python.framework/Versions/3.12/lib/python3.12/urllib/request.py", line 492, in _call_chain
    result = func(*args)
             ^^^^^^^^^^^
  File "/Users/samgupta/Github/control_loop/control_loop/lib/python3.12/site-packages/chump/connection_pool.py", line 82, in https_open
    if response.raw.will_close:
       ^^^^^^^^^^^^
AttributeError: 'NoneType' object has no attribute 'raw'

2024-07-11 16:08:09 - ERROR - Error in handle_client
Unexpected error: received 1001 (going away); then sent 1001 (going away)
Traceback (most recent call last):
  File "/Users/samgupta/Github/control_loop/webapp/backend/api_server.py", line 53, in handle_client
    message = await asyncio.wait_for(websocket.recv(), timeout=60)
              ^^^^^^^^^^^^^^^^^^^^^^^^^^^^^^^^^^^^^^^^^^^^^^^^^^^^
  File "/Library/Frameworks/Python.framework/Versions/3.12/lib/python3.12/asyncio/tasks.py", line 520, in wait_for
    return await fut
           ^^^^^^^^^
  File "/Users/samgupta/Github/control_loop/control_loop/lib/python3.12/site-packages/websockets/legacy/protocol.py", line 568, in recv
    await self.ensure_open()
  File "/Users/samgupta/Github/control_loop/control_loop/lib/python3.12/site-packages/websockets/legacy/protocol.py", line 939, in ensure_open
    raise self.connection_closed_exc()
websockets.exceptions.ConnectionClosedOK: received 1001 (going away); then sent 1001 (going away)

2024-07-11 16:44:24 - ERROR - Error in handle_client
Unexpected error: 
Traceback (most recent call last):
  File "/Library/Frameworks/Python.framework/Versions/3.12/lib/python3.12/asyncio/tasks.py", line 520, in wait_for
    return await fut
           ^^^^^^^^^
  File "/Users/samgupta/Github/control_loop/control_loop/lib/python3.12/site-packages/websockets/legacy/protocol.py", line 552, in recv
    await asyncio.wait(
  File "/Library/Frameworks/Python.framework/Versions/3.12/lib/python3.12/asyncio/tasks.py", line 464, in wait
    return await _wait(fs, timeout, return_when, loop)
           ^^^^^^^^^^^^^^^^^^^^^^^^^^^^^^^^^^^^^^^^^^^
  File "/Library/Frameworks/Python.framework/Versions/3.12/lib/python3.12/asyncio/tasks.py", line 550, in _wait
    await waiter
asyncio.exceptions.CancelledError

The above exception was the direct cause of the following exception:

Traceback (most recent call last):
  File "/Users/samgupta/Github/control_loop/webapp/backend/api_server.py", line 53, in handle_client
    message = await asyncio.wait_for(websocket.recv(), timeout=60)
              ^^^^^^^^^^^^^^^^^^^^^^^^^^^^^^^^^^^^^^^^^^^^^^^^^^^^
  File "/Library/Frameworks/Python.framework/Versions/3.12/lib/python3.12/asyncio/tasks.py", line 519, in wait_for
    async with timeouts.timeout(timeout):
  File "/Library/Frameworks/Python.framework/Versions/3.12/lib/python3.12/asyncio/timeouts.py", line 115, in __aexit__
    raise TimeoutError from exc_val
TimeoutError

2024-07-11 16:44:24 - ERROR - Error in handle_client
Unexpected error: 
Traceback (most recent call last):
  File "/Library/Frameworks/Python.framework/Versions/3.12/lib/python3.12/asyncio/tasks.py", line 520, in wait_for
    return await fut
           ^^^^^^^^^
  File "/Users/samgupta/Github/control_loop/control_loop/lib/python3.12/site-packages/websockets/legacy/protocol.py", line 552, in recv
    await asyncio.wait(
  File "/Library/Frameworks/Python.framework/Versions/3.12/lib/python3.12/asyncio/tasks.py", line 464, in wait
    return await _wait(fs, timeout, return_when, loop)
           ^^^^^^^^^^^^^^^^^^^^^^^^^^^^^^^^^^^^^^^^^^^
  File "/Library/Frameworks/Python.framework/Versions/3.12/lib/python3.12/asyncio/tasks.py", line 550, in _wait
    await waiter
asyncio.exceptions.CancelledError

The above exception was the direct cause of the following exception:

Traceback (most recent call last):
  File "/Users/samgupta/Github/control_loop/webapp/backend/api_server.py", line 53, in handle_client
    message = await asyncio.wait_for(websocket.recv(), timeout=60)
              ^^^^^^^^^^^^^^^^^^^^^^^^^^^^^^^^^^^^^^^^^^^^^^^^^^^^
  File "/Library/Frameworks/Python.framework/Versions/3.12/lib/python3.12/asyncio/tasks.py", line 519, in wait_for
    async with timeouts.timeout(timeout):
  File "/Library/Frameworks/Python.framework/Versions/3.12/lib/python3.12/asyncio/timeouts.py", line 115, in __aexit__
    raise TimeoutError from exc_val
TimeoutError

2024-07-11 16:44:24 - ERROR - Error in send_notification: 'NoneType' object has no attribute 'raw'
Traceback (most recent call last):
  File "/Library/Frameworks/Python.framework/Versions/3.12/lib/python3.12/asyncio/tasks.py", line 520, in wait_for
    return await fut
           ^^^^^^^^^
  File "/Users/samgupta/Github/control_loop/control_loop/lib/python3.12/site-packages/websockets/legacy/protocol.py", line 552, in recv
    await asyncio.wait(
  File "/Library/Frameworks/Python.framework/Versions/3.12/lib/python3.12/asyncio/tasks.py", line 464, in wait
    return await _wait(fs, timeout, return_when, loop)
           ^^^^^^^^^^^^^^^^^^^^^^^^^^^^^^^^^^^^^^^^^^^
  File "/Library/Frameworks/Python.framework/Versions/3.12/lib/python3.12/asyncio/tasks.py", line 550, in _wait
    await waiter
asyncio.exceptions.CancelledError

The above exception was the direct cause of the following exception:

Traceback (most recent call last):
  File "/Users/samgupta/Github/control_loop/webapp/backend/api_server.py", line 53, in handle_client
    message = await asyncio.wait_for(websocket.recv(), timeout=60)
              ^^^^^^^^^^^^^^^^^^^^^^^^^^^^^^^^^^^^^^^^^^^^^^^^^^^^
  File "/Library/Frameworks/Python.framework/Versions/3.12/lib/python3.12/asyncio/tasks.py", line 519, in wait_for
    async with timeouts.timeout(timeout):
  File "/Library/Frameworks/Python.framework/Versions/3.12/lib/python3.12/asyncio/timeouts.py", line 115, in __aexit__
    raise TimeoutError from exc_val
TimeoutError

During handling of the above exception, another exception occurred:

Traceback (most recent call last):
  File "/Users/samgupta/Github/control_loop/webapp/backend/../../src/resources/error_notification.py", line 12, in send_notification
    print(user.is_authenticated, user.devices)
          ^^^^^^^^^^^^^^^^^^^^^
  File "/Users/samgupta/Github/control_loop/control_loop/lib/python3.12/site-packages/chump/__init__.py", line 400, in is_authenticated
    self._authenticate()
  File "/Users/samgupta/Github/control_loop/control_loop/lib/python3.12/site-packages/chump/__init__.py", line 469, in _authenticate
    response, _ = self.app._request('validate', {'user': self.token})
                  ^^^^^^^^^^^^^^^^^^^^^^^^^^^^^^^^^^^^^^^^^^^^^^^^^^^
  File "/Users/samgupta/Github/control_loop/control_loop/lib/python3.12/site-packages/chump/__init__.py", line 337, in _request
    response = pool.open(url, bytes(urlencode(data), 'utf-8', 'strict') if data else None)
               ^^^^^^^^^^^^^^^^^^^^^^^^^^^^^^^^^^^^^^^^^^^^^^^^^^^^^^^^^^^^^^^^^^^^^^^^^^^
  File "/Library/Frameworks/Python.framework/Versions/3.12/lib/python3.12/urllib/request.py", line 515, in open
    response = self._open(req, data)
               ^^^^^^^^^^^^^^^^^^^^^
  File "/Library/Frameworks/Python.framework/Versions/3.12/lib/python3.12/urllib/request.py", line 532, in _open
    result = self._call_chain(self.handle_open, protocol, protocol +
             ^^^^^^^^^^^^^^^^^^^^^^^^^^^^^^^^^^^^^^^^^^^^^^^^^^^^^^^
  File "/Library/Frameworks/Python.framework/Versions/3.12/lib/python3.12/urllib/request.py", line 492, in _call_chain
    result = func(*args)
             ^^^^^^^^^^^
  File "/Users/samgupta/Github/control_loop/control_loop/lib/python3.12/site-packages/chump/connection_pool.py", line 82, in https_open
    if response.raw.will_close:
       ^^^^^^^^^^^^
AttributeError: 'NoneType' object has no attribute 'raw'

2024-07-11 16:44:24 - ERROR - Backup Server Starting
2024-07-11 16:44:24 - ERROR - Error in get_controller: 
 Input: fermentation_loop, 
 [Errno 65] No route to host
Traceback (most recent call last):
  File "/Library/Frameworks/Python.framework/Versions/3.12/lib/python3.12/asyncio/tasks.py", line 520, in wait_for
    return await fut
           ^^^^^^^^^
  File "/Users/samgupta/Github/control_loop/control_loop/lib/python3.12/site-packages/websockets/legacy/protocol.py", line 552, in recv
    await asyncio.wait(
  File "/Library/Frameworks/Python.framework/Versions/3.12/lib/python3.12/asyncio/tasks.py", line 464, in wait
    return await _wait(fs, timeout, return_when, loop)
           ^^^^^^^^^^^^^^^^^^^^^^^^^^^^^^^^^^^^^^^^^^^
  File "/Library/Frameworks/Python.framework/Versions/3.12/lib/python3.12/asyncio/tasks.py", line 550, in _wait
    await waiter
asyncio.exceptions.CancelledError

The above exception was the direct cause of the following exception:

Traceback (most recent call last):
  File "/Users/samgupta/Github/control_loop/webapp/backend/api_server.py", line 53, in handle_client
    message = await asyncio.wait_for(websocket.recv(), timeout=60)
              ^^^^^^^^^^^^^^^^^^^^^^^^^^^^^^^^^^^^^^^^^^^^^^^^^^^^
  File "/Library/Frameworks/Python.framework/Versions/3.12/lib/python3.12/asyncio/tasks.py", line 519, in wait_for
    async with timeouts.timeout(timeout):
  File "/Library/Frameworks/Python.framework/Versions/3.12/lib/python3.12/asyncio/timeouts.py", line 115, in __aexit__
    raise TimeoutError from exc_val
TimeoutError

During handling of the above exception, another exception occurred:

Traceback (most recent call last):
  File "/Users/samgupta/Github/control_loop/webapp/backend/manager_server.py", line 270, in get_controller
    controller = c.create_controller(loop_id)
                 ^^^^^^^^^^^^^^^^^^^^^^^^^^^^
  File "/Users/samgupta/Github/control_loop/webapp/backend/../../src/controllers_mqtt.py", line 41, in create_controller
    controller = FermentationController()
                 ^^^^^^^^^^^^^^^^^^^^^^^^
  File "/Users/samgupta/Github/control_loop/webapp/backend/../../src/controllers_mqtt.py", line 518, in __init__
    self.mqtt_client = ControllerMQTTClient(broker_address="192.168.0.25")
                       ^^^^^^^^^^^^^^^^^^^^^^^^^^^^^^^^^^^^^^^^^^^^^^^^^^^
  File "/Users/samgupta/Github/control_loop/webapp/backend/../../src/controller_mqtt_client.py", line 9, in __init__
    self.client.connect(broker_address, 1883, 60)
  File "/Users/samgupta/Github/control_loop/control_loop/lib/python3.12/site-packages/paho/mqtt/client.py", line 1435, in connect
    return self.reconnect()
           ^^^^^^^^^^^^^^^^
  File "/Users/samgupta/Github/control_loop/control_loop/lib/python3.12/site-packages/paho/mqtt/client.py", line 1598, in reconnect
    self._sock = self._create_socket()
                 ^^^^^^^^^^^^^^^^^^^^^
  File "/Users/samgupta/Github/control_loop/control_loop/lib/python3.12/site-packages/paho/mqtt/client.py", line 4609, in _create_socket
    sock = self._create_socket_connection()
           ^^^^^^^^^^^^^^^^^^^^^^^^^^^^^^^^
  File "/Users/samgupta/Github/control_loop/control_loop/lib/python3.12/site-packages/paho/mqtt/client.py", line 4640, in _create_socket_connection
    return socket.create_connection(addr, timeout=self._connect_timeout, source_address=source)
           ^^^^^^^^^^^^^^^^^^^^^^^^^^^^^^^^^^^^^^^^^^^^^^^^^^^^^^^^^^^^^^^^^^^^^^^^^^^^^^^^^^^^
  File "/Library/Frameworks/Python.framework/Versions/3.12/lib/python3.12/socket.py", line 853, in create_connection
    raise exceptions[0]
  File "/Library/Frameworks/Python.framework/Versions/3.12/lib/python3.12/socket.py", line 838, in create_connection
    sock.connect(sa)
OSError: [Errno 65] No route to host

2024-07-11 16:44:24 - ERROR - Error in handle_server_error
Unexpected error: argument of type 'NoneType' is not iterable
Traceback (most recent call last):
  File "/Library/Frameworks/Python.framework/Versions/3.12/lib/python3.12/asyncio/tasks.py", line 520, in wait_for
    return await fut
           ^^^^^^^^^
  File "/Users/samgupta/Github/control_loop/control_loop/lib/python3.12/site-packages/websockets/legacy/protocol.py", line 552, in recv
    await asyncio.wait(
  File "/Library/Frameworks/Python.framework/Versions/3.12/lib/python3.12/asyncio/tasks.py", line 464, in wait
    return await _wait(fs, timeout, return_when, loop)
           ^^^^^^^^^^^^^^^^^^^^^^^^^^^^^^^^^^^^^^^^^^^
  File "/Library/Frameworks/Python.framework/Versions/3.12/lib/python3.12/asyncio/tasks.py", line 550, in _wait
    await waiter
asyncio.exceptions.CancelledError

The above exception was the direct cause of the following exception:

Traceback (most recent call last):
  File "/Users/samgupta/Github/control_loop/webapp/backend/api_server.py", line 53, in handle_client
    message = await asyncio.wait_for(websocket.recv(), timeout=60)
              ^^^^^^^^^^^^^^^^^^^^^^^^^^^^^^^^^^^^^^^^^^^^^^^^^^^^
  File "/Library/Frameworks/Python.framework/Versions/3.12/lib/python3.12/asyncio/tasks.py", line 519, in wait_for
    async with timeouts.timeout(timeout):
  File "/Library/Frameworks/Python.framework/Versions/3.12/lib/python3.12/asyncio/timeouts.py", line 115, in __aexit__
    raise TimeoutError from exc_val
TimeoutError

During handling of the above exception, another exception occurred:

Traceback (most recent call last):
  File "/Users/samgupta/Github/control_loop/webapp/backend/api_server.py", line 144, in handle_server_error
    controller = await manager_server.stop_all(loop_id)
                 ^^^^^^^^^^^^^^^^^^^^^^^^^^^^^^^^^^^^^^
  File "/Users/samgupta/Github/control_loop/webapp/backend/manager_server.py", line 191, in stop_all
    if "control_task" in controller_info:
       ^^^^^^^^^^^^^^^^^^^^^^^^^^^^^^^^^
TypeError: argument of type 'NoneType' is not iterable

2024-07-11 16:44:24 - ERROR - Error in send_notification: 'NoneType' object has no attribute 'raw'
Traceback (most recent call last):
  File "/Library/Frameworks/Python.framework/Versions/3.12/lib/python3.12/asyncio/tasks.py", line 520, in wait_for
    return await fut
           ^^^^^^^^^
  File "/Users/samgupta/Github/control_loop/control_loop/lib/python3.12/site-packages/websockets/legacy/protocol.py", line 552, in recv
    await asyncio.wait(
  File "/Library/Frameworks/Python.framework/Versions/3.12/lib/python3.12/asyncio/tasks.py", line 464, in wait
    return await _wait(fs, timeout, return_when, loop)
           ^^^^^^^^^^^^^^^^^^^^^^^^^^^^^^^^^^^^^^^^^^^
  File "/Library/Frameworks/Python.framework/Versions/3.12/lib/python3.12/asyncio/tasks.py", line 550, in _wait
    await waiter
asyncio.exceptions.CancelledError

The above exception was the direct cause of the following exception:

Traceback (most recent call last):
  File "/Users/samgupta/Github/control_loop/webapp/backend/api_server.py", line 53, in handle_client
    message = await asyncio.wait_for(websocket.recv(), timeout=60)
              ^^^^^^^^^^^^^^^^^^^^^^^^^^^^^^^^^^^^^^^^^^^^^^^^^^^^
  File "/Library/Frameworks/Python.framework/Versions/3.12/lib/python3.12/asyncio/tasks.py", line 519, in wait_for
    async with timeouts.timeout(timeout):
  File "/Library/Frameworks/Python.framework/Versions/3.12/lib/python3.12/asyncio/timeouts.py", line 115, in __aexit__
    raise TimeoutError from exc_val
TimeoutError

During handling of the above exception, another exception occurred:

Traceback (most recent call last):
  File "/Users/samgupta/Github/control_loop/webapp/backend/api_server.py", line 144, in handle_server_error
    controller = await manager_server.stop_all(loop_id)
                 ^^^^^^^^^^^^^^^^^^^^^^^^^^^^^^^^^^^^^^
  File "/Users/samgupta/Github/control_loop/webapp/backend/manager_server.py", line 191, in stop_all
    if "control_task" in controller_info:
       ^^^^^^^^^^^^^^^^^^^^^^^^^^^^^^^^^
TypeError: argument of type 'NoneType' is not iterable

During handling of the above exception, another exception occurred:

Traceback (most recent call last):
  File "/Users/samgupta/Github/control_loop/webapp/backend/../../src/resources/error_notification.py", line 12, in send_notification
    print(user.is_authenticated, user.devices)
          ^^^^^^^^^^^^^^^^^^^^^
  File "/Users/samgupta/Github/control_loop/control_loop/lib/python3.12/site-packages/chump/__init__.py", line 400, in is_authenticated
    self._authenticate()
  File "/Users/samgupta/Github/control_loop/control_loop/lib/python3.12/site-packages/chump/__init__.py", line 469, in _authenticate
    response, _ = self.app._request('validate', {'user': self.token})
                  ^^^^^^^^^^^^^^^^^^^^^^^^^^^^^^^^^^^^^^^^^^^^^^^^^^^
  File "/Users/samgupta/Github/control_loop/control_loop/lib/python3.12/site-packages/chump/__init__.py", line 337, in _request
    response = pool.open(url, bytes(urlencode(data), 'utf-8', 'strict') if data else None)
               ^^^^^^^^^^^^^^^^^^^^^^^^^^^^^^^^^^^^^^^^^^^^^^^^^^^^^^^^^^^^^^^^^^^^^^^^^^^
  File "/Library/Frameworks/Python.framework/Versions/3.12/lib/python3.12/urllib/request.py", line 515, in open
    response = self._open(req, data)
               ^^^^^^^^^^^^^^^^^^^^^
  File "/Library/Frameworks/Python.framework/Versions/3.12/lib/python3.12/urllib/request.py", line 532, in _open
    result = self._call_chain(self.handle_open, protocol, protocol +
             ^^^^^^^^^^^^^^^^^^^^^^^^^^^^^^^^^^^^^^^^^^^^^^^^^^^^^^^
  File "/Library/Frameworks/Python.framework/Versions/3.12/lib/python3.12/urllib/request.py", line 492, in _call_chain
    result = func(*args)
             ^^^^^^^^^^^
  File "/Users/samgupta/Github/control_loop/control_loop/lib/python3.12/site-packages/chump/connection_pool.py", line 82, in https_open
    if response.raw.will_close:
       ^^^^^^^^^^^^
AttributeError: 'NoneType' object has no attribute 'raw'

