2024-07-04 16:40:40 - ERROR - Error in handle_client
Unexpected error: no close frame received or sent
Traceback (most recent call last):
  File "/home/sam/Desktop/control_loop/env/lib/python3.10/site-packages/websockets/legacy/protocol.py", line 963, in transfer_data
    message = await self.read_message()
  File "/home/sam/Desktop/control_loop/env/lib/python3.10/site-packages/websockets/legacy/protocol.py", line 1033, in read_message
    frame = await self.read_data_frame(max_size=self.max_size)
  File "/home/sam/Desktop/control_loop/env/lib/python3.10/site-packages/websockets/legacy/protocol.py", line 1108, in read_data_frame
    frame = await self.read_frame(max_size)
  File "/home/sam/Desktop/control_loop/env/lib/python3.10/site-packages/websockets/legacy/protocol.py", line 1165, in read_frame
    frame = await Frame.read(
  File "/home/sam/Desktop/control_loop/env/lib/python3.10/site-packages/websockets/legacy/framing.py", line 68, in read
    data = await reader(2)
  File "/usr/lib/python3.10/asyncio/streams.py", line 706, in readexactly
    raise exceptions.IncompleteReadError(incomplete, n)
asyncio.exceptions.IncompleteReadError: 0 bytes read on a total of 2 expected bytes

The above exception was the direct cause of the following exception:

Traceback (most recent call last):
  File "/home/sam/Desktop/control_loop/webapp/backend/api_server.py", line 53, in handle_client
    message = await asyncio.wait_for(websocket.recv(), timeout=60)
  File "/usr/lib/python3.10/asyncio/tasks.py", line 445, in wait_for
    return fut.result()
  File "/home/sam/Desktop/control_loop/env/lib/python3.10/site-packages/websockets/legacy/protocol.py", line 568, in recv
    await self.ensure_open()
  File "/home/sam/Desktop/control_loop/env/lib/python3.10/site-packages/websockets/legacy/protocol.py", line 939, in ensure_open
    raise self.connection_closed_exc()
websockets.exceptions.ConnectionClosedError: no close frame received or sent

2024-07-05 01:50:41 - ERROR - Error in handle_client
Unexpected error: 
Traceback (most recent call last):
  File "/home/sam/Desktop/control_loop/env/lib/python3.10/site-packages/websockets/legacy/protocol.py", line 552, in recv
    await asyncio.wait(
  File "/usr/lib/python3.10/asyncio/tasks.py", line 384, in wait
    return await _wait(fs, timeout, return_when, loop)
  File "/usr/lib/python3.10/asyncio/tasks.py", line 491, in _wait
    await waiter
asyncio.exceptions.CancelledError

During handling of the above exception, another exception occurred:

Traceback (most recent call last):
  File "/usr/lib/python3.10/asyncio/tasks.py", line 456, in wait_for
    return fut.result()
asyncio.exceptions.CancelledError

The above exception was the direct cause of the following exception:

Traceback (most recent call last):
  File "/home/sam/Desktop/control_loop/webapp/backend/api_server.py", line 53, in handle_client
    message = await asyncio.wait_for(websocket.recv(), timeout=60)
  File "/usr/lib/python3.10/asyncio/tasks.py", line 458, in wait_for
    raise exceptions.TimeoutError() from exc
asyncio.exceptions.TimeoutError

2024-07-05 01:50:41 - ERROR - Error in handle_client
Unexpected error: 
Traceback (most recent call last):
  File "/home/sam/Desktop/control_loop/env/lib/python3.10/site-packages/websockets/legacy/protocol.py", line 552, in recv
    await asyncio.wait(
  File "/usr/lib/python3.10/asyncio/tasks.py", line 384, in wait
    return await _wait(fs, timeout, return_when, loop)
  File "/usr/lib/python3.10/asyncio/tasks.py", line 491, in _wait
    await waiter
asyncio.exceptions.CancelledError

During handling of the above exception, another exception occurred:

Traceback (most recent call last):
  File "/usr/lib/python3.10/asyncio/tasks.py", line 456, in wait_for
    return fut.result()
asyncio.exceptions.CancelledError

The above exception was the direct cause of the following exception:

Traceback (most recent call last):
  File "/home/sam/Desktop/control_loop/webapp/backend/api_server.py", line 53, in handle_client
    message = await asyncio.wait_for(websocket.recv(), timeout=60)
  File "/usr/lib/python3.10/asyncio/tasks.py", line 458, in wait_for
    raise exceptions.TimeoutError() from exc
asyncio.exceptions.TimeoutError

2024-07-05 01:50:41 - ERROR - Error in send_notification: Bad message: must be 0-1024 characters, was 1101
Traceback (most recent call last):
  File "/home/sam/Desktop/control_loop/env/lib/python3.10/site-packages/websockets/legacy/protocol.py", line 552, in recv
    await asyncio.wait(
  File "/usr/lib/python3.10/asyncio/tasks.py", line 384, in wait
    return await _wait(fs, timeout, return_when, loop)
  File "/usr/lib/python3.10/asyncio/tasks.py", line 491, in _wait
    await waiter
asyncio.exceptions.CancelledError

During handling of the above exception, another exception occurred:

Traceback (most recent call last):
  File "/usr/lib/python3.10/asyncio/tasks.py", line 456, in wait_for
    return fut.result()
asyncio.exceptions.CancelledError

The above exception was the direct cause of the following exception:

Traceback (most recent call last):
  File "/home/sam/Desktop/control_loop/webapp/backend/api_server.py", line 53, in handle_client
    message = await asyncio.wait_for(websocket.recv(), timeout=60)
  File "/usr/lib/python3.10/asyncio/tasks.py", line 458, in wait_for
    raise exceptions.TimeoutError() from exc
asyncio.exceptions.TimeoutError

During handling of the above exception, another exception occurred:

Traceback (most recent call last):
  File "/home/sam/Desktop/control_loop/webapp/backend/../../src/resources/error_notification.py", line 18, in send_notification
    message = user.send_message(f"{message}", priority=priority)
  File "/home/sam/Desktop/control_loop/env/lib/python3.10/site-packages/chump/__init__.py", line 563, in send_message
    message = self.create_message(
  File "/home/sam/Desktop/control_loop/env/lib/python3.10/site-packages/chump/__init__.py", line 549, in create_message
    return message_class(self, **kwargs)
  File "/home/sam/Desktop/control_loop/env/lib/python3.10/site-packages/chump/__init__.py", line 781, in __init__
    super(EmergencyMessage, self).__init__(
  File "/home/sam/Desktop/control_loop/env/lib/python3.10/site-packages/chump/__init__.py", line 590, in __init__
    self.message = message
  File "/home/sam/Desktop/control_loop/env/lib/python3.10/site-packages/chump/__init__.py", line 825, in __setattr__
    super(EmergencyMessage, self).__setattr__(name, value)
  File "/home/sam/Desktop/control_loop/env/lib/python3.10/site-packages/chump/__init__.py", line 645, in __setattr__
    raise ValueError('Bad message: must be 0-1024 characters, was {length}'.format(length=len(value)))
ValueError: Bad message: must be 0-1024 characters, was 1101

2024-07-05 01:50:41 - ERROR - Backup Server Starting
2024-07-05 02:54:08 - ERROR - Error in save_dict_to_sheet: ('Connection aborted.', RemoteDisconnected('Remote end closed connection without response'))
Traceback (most recent call last):
  File "/home/sam/Desktop/control_loop/env/lib/python3.10/site-packages/websockets/legacy/protocol.py", line 552, in recv
    await asyncio.wait(
  File "/usr/lib/python3.10/asyncio/tasks.py", line 384, in wait
    return await _wait(fs, timeout, return_when, loop)
  File "/usr/lib/python3.10/asyncio/tasks.py", line 491, in _wait
    await waiter
asyncio.exceptions.CancelledError

During handling of the above exception, another exception occurred:

Traceback (most recent call last):
  File "/usr/lib/python3.10/asyncio/tasks.py", line 456, in wait_for
    return fut.result()
asyncio.exceptions.CancelledError

The above exception was the direct cause of the following exception:

Traceback (most recent call last):
  File "/home/sam/Desktop/control_loop/webapp/backend/api_server.py", line 53, in handle_client
    message = await asyncio.wait_for(websocket.recv(), timeout=60)
  File "/usr/lib/python3.10/asyncio/tasks.py", line 458, in wait_for
    raise exceptions.TimeoutError() from exc
asyncio.exceptions.TimeoutError

During handling of the above exception, another exception occurred:

Traceback (most recent call last):
  File "/home/sam/Desktop/control_loop/env/lib/python3.10/site-packages/urllib3/connectionpool.py", line 793, in urlopen
    response = self._make_request(
  File "/home/sam/Desktop/control_loop/env/lib/python3.10/site-packages/urllib3/connectionpool.py", line 537, in _make_request
    response = conn.getresponse()
  File "/home/sam/Desktop/control_loop/env/lib/python3.10/site-packages/urllib3/connection.py", line 466, in getresponse
    httplib_response = super().getresponse()
  File "/usr/lib/python3.10/http/client.py", line 1375, in getresponse
    response.begin()
  File "/usr/lib/python3.10/http/client.py", line 318, in begin
    version, status, reason = self._read_status()
  File "/usr/lib/python3.10/http/client.py", line 287, in _read_status
    raise RemoteDisconnected("Remote end closed connection without"
http.client.RemoteDisconnected: Remote end closed connection without response

During handling of the above exception, another exception occurred:

Traceback (most recent call last):
  File "/home/sam/Desktop/control_loop/env/lib/python3.10/site-packages/requests/adapters.py", line 589, in send
    resp = conn.urlopen(
  File "/home/sam/Desktop/control_loop/env/lib/python3.10/site-packages/urllib3/connectionpool.py", line 847, in urlopen
    retries = retries.increment(
  File "/home/sam/Desktop/control_loop/env/lib/python3.10/site-packages/urllib3/util/retry.py", line 470, in increment
    raise reraise(type(error), error, _stacktrace)
  File "/home/sam/Desktop/control_loop/env/lib/python3.10/site-packages/urllib3/util/util.py", line 38, in reraise
    raise value.with_traceback(tb)
  File "/home/sam/Desktop/control_loop/env/lib/python3.10/site-packages/urllib3/connectionpool.py", line 793, in urlopen
    response = self._make_request(
  File "/home/sam/Desktop/control_loop/env/lib/python3.10/site-packages/urllib3/connectionpool.py", line 537, in _make_request
    response = conn.getresponse()
  File "/home/sam/Desktop/control_loop/env/lib/python3.10/site-packages/urllib3/connection.py", line 466, in getresponse
    httplib_response = super().getresponse()
  File "/usr/lib/python3.10/http/client.py", line 1375, in getresponse
    response.begin()
  File "/usr/lib/python3.10/http/client.py", line 318, in begin
    version, status, reason = self._read_status()
  File "/usr/lib/python3.10/http/client.py", line 287, in _read_status
    raise RemoteDisconnected("Remote end closed connection without"
urllib3.exceptions.ProtocolError: ('Connection aborted.', RemoteDisconnected('Remote end closed connection without response'))

During handling of the above exception, another exception occurred:

Traceback (most recent call last):
  File "/home/sam/Desktop/control_loop/webapp/backend/../../src/resources/google_api/sheets.py", line 104, in save_dict_to_sheet
    spreadsheet = client.open(sheet_name)
  File "/home/sam/Desktop/control_loop/env/lib/python3.10/site-packages/gspread/client.py", line 132, in open
    spreadsheet_files, response = self._list_spreadsheet_files(title, folder_id)
  File "/home/sam/Desktop/control_loop/env/lib/python3.10/site-packages/gspread/client.py", line 105, in _list_spreadsheet_files
    response = self.http_client.request("get", url, params=params)
  File "/home/sam/Desktop/control_loop/env/lib/python3.10/site-packages/gspread/http_client.py", line 114, in request
    response = self.session.request(
  File "/home/sam/Desktop/control_loop/env/lib/python3.10/site-packages/google/auth/transport/requests.py", line 541, in request
    response = super(AuthorizedSession, self).request(
  File "/home/sam/Desktop/control_loop/env/lib/python3.10/site-packages/requests/sessions.py", line 589, in request
    resp = self.send(prep, **send_kwargs)
  File "/home/sam/Desktop/control_loop/env/lib/python3.10/site-packages/requests/sessions.py", line 703, in send
    r = adapter.send(request, **kwargs)
  File "/home/sam/Desktop/control_loop/env/lib/python3.10/site-packages/requests/adapters.py", line 604, in send
    raise ConnectionError(err, request=request)
requests.exceptions.ConnectionError: ('Connection aborted.', RemoteDisconnected('Remote end closed connection without response'))

2024-07-05 03:39:29 - ERROR - Error in save_dict_to_sheet: ('Connection aborted.', RemoteDisconnected('Remote end closed connection without response'))
Traceback (most recent call last):
  File "/home/sam/Desktop/control_loop/env/lib/python3.10/site-packages/websockets/legacy/protocol.py", line 552, in recv
    await asyncio.wait(
  File "/usr/lib/python3.10/asyncio/tasks.py", line 384, in wait
    return await _wait(fs, timeout, return_when, loop)
  File "/usr/lib/python3.10/asyncio/tasks.py", line 491, in _wait
    await waiter
asyncio.exceptions.CancelledError

During handling of the above exception, another exception occurred:

Traceback (most recent call last):
  File "/usr/lib/python3.10/asyncio/tasks.py", line 456, in wait_for
    return fut.result()
asyncio.exceptions.CancelledError

The above exception was the direct cause of the following exception:

Traceback (most recent call last):
  File "/home/sam/Desktop/control_loop/webapp/backend/api_server.py", line 53, in handle_client
    message = await asyncio.wait_for(websocket.recv(), timeout=60)
  File "/usr/lib/python3.10/asyncio/tasks.py", line 458, in wait_for
    raise exceptions.TimeoutError() from exc
asyncio.exceptions.TimeoutError

During handling of the above exception, another exception occurred:

Traceback (most recent call last):
  File "/home/sam/Desktop/control_loop/env/lib/python3.10/site-packages/urllib3/connectionpool.py", line 793, in urlopen
    response = self._make_request(
  File "/home/sam/Desktop/control_loop/env/lib/python3.10/site-packages/urllib3/connectionpool.py", line 537, in _make_request
    response = conn.getresponse()
  File "/home/sam/Desktop/control_loop/env/lib/python3.10/site-packages/urllib3/connection.py", line 466, in getresponse
    httplib_response = super().getresponse()
  File "/usr/lib/python3.10/http/client.py", line 1375, in getresponse
    response.begin()
  File "/usr/lib/python3.10/http/client.py", line 318, in begin
    version, status, reason = self._read_status()
  File "/usr/lib/python3.10/http/client.py", line 287, in _read_status
    raise RemoteDisconnected("Remote end closed connection without"
http.client.RemoteDisconnected: Remote end closed connection without response

During handling of the above exception, another exception occurred:

Traceback (most recent call last):
  File "/home/sam/Desktop/control_loop/env/lib/python3.10/site-packages/requests/adapters.py", line 589, in send
    resp = conn.urlopen(
  File "/home/sam/Desktop/control_loop/env/lib/python3.10/site-packages/urllib3/connectionpool.py", line 847, in urlopen
    retries = retries.increment(
  File "/home/sam/Desktop/control_loop/env/lib/python3.10/site-packages/urllib3/util/retry.py", line 470, in increment
    raise reraise(type(error), error, _stacktrace)
  File "/home/sam/Desktop/control_loop/env/lib/python3.10/site-packages/urllib3/util/util.py", line 38, in reraise
    raise value.with_traceback(tb)
  File "/home/sam/Desktop/control_loop/env/lib/python3.10/site-packages/urllib3/connectionpool.py", line 793, in urlopen
    response = self._make_request(
  File "/home/sam/Desktop/control_loop/env/lib/python3.10/site-packages/urllib3/connectionpool.py", line 537, in _make_request
    response = conn.getresponse()
  File "/home/sam/Desktop/control_loop/env/lib/python3.10/site-packages/urllib3/connection.py", line 466, in getresponse
    httplib_response = super().getresponse()
  File "/usr/lib/python3.10/http/client.py", line 1375, in getresponse
    response.begin()
  File "/usr/lib/python3.10/http/client.py", line 318, in begin
    version, status, reason = self._read_status()
  File "/usr/lib/python3.10/http/client.py", line 287, in _read_status
    raise RemoteDisconnected("Remote end closed connection without"
urllib3.exceptions.ProtocolError: ('Connection aborted.', RemoteDisconnected('Remote end closed connection without response'))

During handling of the above exception, another exception occurred:

Traceback (most recent call last):
  File "/home/sam/Desktop/control_loop/webapp/backend/../../src/resources/google_api/sheets.py", line 104, in save_dict_to_sheet
    spreadsheet = client.open(sheet_name)
  File "/home/sam/Desktop/control_loop/env/lib/python3.10/site-packages/gspread/client.py", line 132, in open
    spreadsheet_files, response = self._list_spreadsheet_files(title, folder_id)
  File "/home/sam/Desktop/control_loop/env/lib/python3.10/site-packages/gspread/client.py", line 105, in _list_spreadsheet_files
    response = self.http_client.request("get", url, params=params)
  File "/home/sam/Desktop/control_loop/env/lib/python3.10/site-packages/gspread/http_client.py", line 114, in request
    response = self.session.request(
  File "/home/sam/Desktop/control_loop/env/lib/python3.10/site-packages/google/auth/transport/requests.py", line 541, in request
    response = super(AuthorizedSession, self).request(
  File "/home/sam/Desktop/control_loop/env/lib/python3.10/site-packages/requests/sessions.py", line 589, in request
    resp = self.send(prep, **send_kwargs)
  File "/home/sam/Desktop/control_loop/env/lib/python3.10/site-packages/requests/sessions.py", line 703, in send
    r = adapter.send(request, **kwargs)
  File "/home/sam/Desktop/control_loop/env/lib/python3.10/site-packages/requests/adapters.py", line 604, in send
    raise ConnectionError(err, request=request)
requests.exceptions.ConnectionError: ('Connection aborted.', RemoteDisconnected('Remote end closed connection without response'))

2024-07-05 05:52:48 - ERROR - Error in save_dict_to_sheet: ('Connection aborted.', RemoteDisconnected('Remote end closed connection without response'))
Traceback (most recent call last):
  File "/home/sam/Desktop/control_loop/env/lib/python3.10/site-packages/websockets/legacy/protocol.py", line 552, in recv
    await asyncio.wait(
  File "/usr/lib/python3.10/asyncio/tasks.py", line 384, in wait
    return await _wait(fs, timeout, return_when, loop)
  File "/usr/lib/python3.10/asyncio/tasks.py", line 491, in _wait
    await waiter
asyncio.exceptions.CancelledError

During handling of the above exception, another exception occurred:

Traceback (most recent call last):
  File "/usr/lib/python3.10/asyncio/tasks.py", line 456, in wait_for
    return fut.result()
asyncio.exceptions.CancelledError

The above exception was the direct cause of the following exception:

Traceback (most recent call last):
  File "/home/sam/Desktop/control_loop/webapp/backend/api_server.py", line 53, in handle_client
    message = await asyncio.wait_for(websocket.recv(), timeout=60)
  File "/usr/lib/python3.10/asyncio/tasks.py", line 458, in wait_for
    raise exceptions.TimeoutError() from exc
asyncio.exceptions.TimeoutError

During handling of the above exception, another exception occurred:

Traceback (most recent call last):
  File "/home/sam/Desktop/control_loop/env/lib/python3.10/site-packages/urllib3/connectionpool.py", line 793, in urlopen
    response = self._make_request(
  File "/home/sam/Desktop/control_loop/env/lib/python3.10/site-packages/urllib3/connectionpool.py", line 537, in _make_request
    response = conn.getresponse()
  File "/home/sam/Desktop/control_loop/env/lib/python3.10/site-packages/urllib3/connection.py", line 466, in getresponse
    httplib_response = super().getresponse()
  File "/usr/lib/python3.10/http/client.py", line 1375, in getresponse
    response.begin()
  File "/usr/lib/python3.10/http/client.py", line 318, in begin
    version, status, reason = self._read_status()
  File "/usr/lib/python3.10/http/client.py", line 287, in _read_status
    raise RemoteDisconnected("Remote end closed connection without"
http.client.RemoteDisconnected: Remote end closed connection without response

During handling of the above exception, another exception occurred:

Traceback (most recent call last):
  File "/home/sam/Desktop/control_loop/env/lib/python3.10/site-packages/requests/adapters.py", line 589, in send
    resp = conn.urlopen(
  File "/home/sam/Desktop/control_loop/env/lib/python3.10/site-packages/urllib3/connectionpool.py", line 847, in urlopen
    retries = retries.increment(
  File "/home/sam/Desktop/control_loop/env/lib/python3.10/site-packages/urllib3/util/retry.py", line 470, in increment
    raise reraise(type(error), error, _stacktrace)
  File "/home/sam/Desktop/control_loop/env/lib/python3.10/site-packages/urllib3/util/util.py", line 38, in reraise
    raise value.with_traceback(tb)
  File "/home/sam/Desktop/control_loop/env/lib/python3.10/site-packages/urllib3/connectionpool.py", line 793, in urlopen
    response = self._make_request(
  File "/home/sam/Desktop/control_loop/env/lib/python3.10/site-packages/urllib3/connectionpool.py", line 537, in _make_request
    response = conn.getresponse()
  File "/home/sam/Desktop/control_loop/env/lib/python3.10/site-packages/urllib3/connection.py", line 466, in getresponse
    httplib_response = super().getresponse()
  File "/usr/lib/python3.10/http/client.py", line 1375, in getresponse
    response.begin()
  File "/usr/lib/python3.10/http/client.py", line 318, in begin
    version, status, reason = self._read_status()
  File "/usr/lib/python3.10/http/client.py", line 287, in _read_status
    raise RemoteDisconnected("Remote end closed connection without"
urllib3.exceptions.ProtocolError: ('Connection aborted.', RemoteDisconnected('Remote end closed connection without response'))

During handling of the above exception, another exception occurred:

Traceback (most recent call last):
  File "/home/sam/Desktop/control_loop/webapp/backend/../../src/resources/google_api/sheets.py", line 104, in save_dict_to_sheet
    spreadsheet = client.open(sheet_name)
  File "/home/sam/Desktop/control_loop/env/lib/python3.10/site-packages/gspread/client.py", line 132, in open
    spreadsheet_files, response = self._list_spreadsheet_files(title, folder_id)
  File "/home/sam/Desktop/control_loop/env/lib/python3.10/site-packages/gspread/client.py", line 105, in _list_spreadsheet_files
    response = self.http_client.request("get", url, params=params)
  File "/home/sam/Desktop/control_loop/env/lib/python3.10/site-packages/gspread/http_client.py", line 114, in request
    response = self.session.request(
  File "/home/sam/Desktop/control_loop/env/lib/python3.10/site-packages/google/auth/transport/requests.py", line 541, in request
    response = super(AuthorizedSession, self).request(
  File "/home/sam/Desktop/control_loop/env/lib/python3.10/site-packages/requests/sessions.py", line 589, in request
    resp = self.send(prep, **send_kwargs)
  File "/home/sam/Desktop/control_loop/env/lib/python3.10/site-packages/requests/sessions.py", line 703, in send
    r = adapter.send(request, **kwargs)
  File "/home/sam/Desktop/control_loop/env/lib/python3.10/site-packages/requests/adapters.py", line 604, in send
    raise ConnectionError(err, request=request)
requests.exceptions.ConnectionError: ('Connection aborted.', RemoteDisconnected('Remote end closed connection without response'))

2024-07-05 07:18:06 - ERROR - Error in save_dict_to_sheet: ('Connection aborted.', RemoteDisconnected('Remote end closed connection without response'))
Traceback (most recent call last):
  File "/home/sam/Desktop/control_loop/env/lib/python3.10/site-packages/websockets/legacy/protocol.py", line 552, in recv
    await asyncio.wait(
  File "/usr/lib/python3.10/asyncio/tasks.py", line 384, in wait
    return await _wait(fs, timeout, return_when, loop)
  File "/usr/lib/python3.10/asyncio/tasks.py", line 491, in _wait
    await waiter
asyncio.exceptions.CancelledError

During handling of the above exception, another exception occurred:

Traceback (most recent call last):
  File "/usr/lib/python3.10/asyncio/tasks.py", line 456, in wait_for
    return fut.result()
asyncio.exceptions.CancelledError

The above exception was the direct cause of the following exception:

Traceback (most recent call last):
  File "/home/sam/Desktop/control_loop/webapp/backend/api_server.py", line 53, in handle_client
    message = await asyncio.wait_for(websocket.recv(), timeout=60)
  File "/usr/lib/python3.10/asyncio/tasks.py", line 458, in wait_for
    raise exceptions.TimeoutError() from exc
asyncio.exceptions.TimeoutError

During handling of the above exception, another exception occurred:

Traceback (most recent call last):
  File "/home/sam/Desktop/control_loop/env/lib/python3.10/site-packages/urllib3/connectionpool.py", line 793, in urlopen
    response = self._make_request(
  File "/home/sam/Desktop/control_loop/env/lib/python3.10/site-packages/urllib3/connectionpool.py", line 537, in _make_request
    response = conn.getresponse()
  File "/home/sam/Desktop/control_loop/env/lib/python3.10/site-packages/urllib3/connection.py", line 466, in getresponse
    httplib_response = super().getresponse()
  File "/usr/lib/python3.10/http/client.py", line 1375, in getresponse
    response.begin()
  File "/usr/lib/python3.10/http/client.py", line 318, in begin
    version, status, reason = self._read_status()
  File "/usr/lib/python3.10/http/client.py", line 287, in _read_status
    raise RemoteDisconnected("Remote end closed connection without"
http.client.RemoteDisconnected: Remote end closed connection without response

During handling of the above exception, another exception occurred:

Traceback (most recent call last):
  File "/home/sam/Desktop/control_loop/env/lib/python3.10/site-packages/requests/adapters.py", line 589, in send
    resp = conn.urlopen(
  File "/home/sam/Desktop/control_loop/env/lib/python3.10/site-packages/urllib3/connectionpool.py", line 847, in urlopen
    retries = retries.increment(
  File "/home/sam/Desktop/control_loop/env/lib/python3.10/site-packages/urllib3/util/retry.py", line 470, in increment
    raise reraise(type(error), error, _stacktrace)
  File "/home/sam/Desktop/control_loop/env/lib/python3.10/site-packages/urllib3/util/util.py", line 38, in reraise
    raise value.with_traceback(tb)
  File "/home/sam/Desktop/control_loop/env/lib/python3.10/site-packages/urllib3/connectionpool.py", line 793, in urlopen
    response = self._make_request(
  File "/home/sam/Desktop/control_loop/env/lib/python3.10/site-packages/urllib3/connectionpool.py", line 537, in _make_request
    response = conn.getresponse()
  File "/home/sam/Desktop/control_loop/env/lib/python3.10/site-packages/urllib3/connection.py", line 466, in getresponse
    httplib_response = super().getresponse()
  File "/usr/lib/python3.10/http/client.py", line 1375, in getresponse
    response.begin()
  File "/usr/lib/python3.10/http/client.py", line 318, in begin
    version, status, reason = self._read_status()
  File "/usr/lib/python3.10/http/client.py", line 287, in _read_status
    raise RemoteDisconnected("Remote end closed connection without"
urllib3.exceptions.ProtocolError: ('Connection aborted.', RemoteDisconnected('Remote end closed connection without response'))

During handling of the above exception, another exception occurred:

Traceback (most recent call last):
  File "/home/sam/Desktop/control_loop/webapp/backend/../../src/resources/google_api/sheets.py", line 104, in save_dict_to_sheet
    spreadsheet = client.open(sheet_name)
  File "/home/sam/Desktop/control_loop/env/lib/python3.10/site-packages/gspread/client.py", line 132, in open
    spreadsheet_files, response = self._list_spreadsheet_files(title, folder_id)
  File "/home/sam/Desktop/control_loop/env/lib/python3.10/site-packages/gspread/client.py", line 105, in _list_spreadsheet_files
    response = self.http_client.request("get", url, params=params)
  File "/home/sam/Desktop/control_loop/env/lib/python3.10/site-packages/gspread/http_client.py", line 114, in request
    response = self.session.request(
  File "/home/sam/Desktop/control_loop/env/lib/python3.10/site-packages/google/auth/transport/requests.py", line 541, in request
    response = super(AuthorizedSession, self).request(
  File "/home/sam/Desktop/control_loop/env/lib/python3.10/site-packages/requests/sessions.py", line 589, in request
    resp = self.send(prep, **send_kwargs)
  File "/home/sam/Desktop/control_loop/env/lib/python3.10/site-packages/requests/sessions.py", line 703, in send
    r = adapter.send(request, **kwargs)
  File "/home/sam/Desktop/control_loop/env/lib/python3.10/site-packages/requests/adapters.py", line 604, in send
    raise ConnectionError(err, request=request)
requests.exceptions.ConnectionError: ('Connection aborted.', RemoteDisconnected('Remote end closed connection without response'))

2024-07-05 08:54:46 - ERROR - Error in save_dict_to_sheet: ('Connection aborted.', RemoteDisconnected('Remote end closed connection without response'))
Traceback (most recent call last):
  File "/home/sam/Desktop/control_loop/env/lib/python3.10/site-packages/websockets/legacy/protocol.py", line 552, in recv
    await asyncio.wait(
  File "/usr/lib/python3.10/asyncio/tasks.py", line 384, in wait
    return await _wait(fs, timeout, return_when, loop)
  File "/usr/lib/python3.10/asyncio/tasks.py", line 491, in _wait
    await waiter
asyncio.exceptions.CancelledError

During handling of the above exception, another exception occurred:

Traceback (most recent call last):
  File "/usr/lib/python3.10/asyncio/tasks.py", line 456, in wait_for
    return fut.result()
asyncio.exceptions.CancelledError

The above exception was the direct cause of the following exception:

Traceback (most recent call last):
  File "/home/sam/Desktop/control_loop/webapp/backend/api_server.py", line 53, in handle_client
    message = await asyncio.wait_for(websocket.recv(), timeout=60)
  File "/usr/lib/python3.10/asyncio/tasks.py", line 458, in wait_for
    raise exceptions.TimeoutError() from exc
asyncio.exceptions.TimeoutError

During handling of the above exception, another exception occurred:

Traceback (most recent call last):
  File "/home/sam/Desktop/control_loop/env/lib/python3.10/site-packages/urllib3/connectionpool.py", line 793, in urlopen
    response = self._make_request(
  File "/home/sam/Desktop/control_loop/env/lib/python3.10/site-packages/urllib3/connectionpool.py", line 537, in _make_request
    response = conn.getresponse()
  File "/home/sam/Desktop/control_loop/env/lib/python3.10/site-packages/urllib3/connection.py", line 466, in getresponse
    httplib_response = super().getresponse()
  File "/usr/lib/python3.10/http/client.py", line 1375, in getresponse
    response.begin()
  File "/usr/lib/python3.10/http/client.py", line 318, in begin
    version, status, reason = self._read_status()
  File "/usr/lib/python3.10/http/client.py", line 287, in _read_status
    raise RemoteDisconnected("Remote end closed connection without"
http.client.RemoteDisconnected: Remote end closed connection without response

During handling of the above exception, another exception occurred:

Traceback (most recent call last):
  File "/home/sam/Desktop/control_loop/env/lib/python3.10/site-packages/requests/adapters.py", line 589, in send
    resp = conn.urlopen(
  File "/home/sam/Desktop/control_loop/env/lib/python3.10/site-packages/urllib3/connectionpool.py", line 847, in urlopen
    retries = retries.increment(
  File "/home/sam/Desktop/control_loop/env/lib/python3.10/site-packages/urllib3/util/retry.py", line 470, in increment
    raise reraise(type(error), error, _stacktrace)
  File "/home/sam/Desktop/control_loop/env/lib/python3.10/site-packages/urllib3/util/util.py", line 38, in reraise
    raise value.with_traceback(tb)
  File "/home/sam/Desktop/control_loop/env/lib/python3.10/site-packages/urllib3/connectionpool.py", line 793, in urlopen
    response = self._make_request(
  File "/home/sam/Desktop/control_loop/env/lib/python3.10/site-packages/urllib3/connectionpool.py", line 537, in _make_request
    response = conn.getresponse()
  File "/home/sam/Desktop/control_loop/env/lib/python3.10/site-packages/urllib3/connection.py", line 466, in getresponse
    httplib_response = super().getresponse()
  File "/usr/lib/python3.10/http/client.py", line 1375, in getresponse
    response.begin()
  File "/usr/lib/python3.10/http/client.py", line 318, in begin
    version, status, reason = self._read_status()
  File "/usr/lib/python3.10/http/client.py", line 287, in _read_status
    raise RemoteDisconnected("Remote end closed connection without"
urllib3.exceptions.ProtocolError: ('Connection aborted.', RemoteDisconnected('Remote end closed connection without response'))

During handling of the above exception, another exception occurred:

Traceback (most recent call last):
  File "/home/sam/Desktop/control_loop/webapp/backend/../../src/resources/google_api/sheets.py", line 104, in save_dict_to_sheet
    spreadsheet = client.open(sheet_name)
  File "/home/sam/Desktop/control_loop/env/lib/python3.10/site-packages/gspread/client.py", line 132, in open
    spreadsheet_files, response = self._list_spreadsheet_files(title, folder_id)
  File "/home/sam/Desktop/control_loop/env/lib/python3.10/site-packages/gspread/client.py", line 105, in _list_spreadsheet_files
    response = self.http_client.request("get", url, params=params)
  File "/home/sam/Desktop/control_loop/env/lib/python3.10/site-packages/gspread/http_client.py", line 114, in request
    response = self.session.request(
  File "/home/sam/Desktop/control_loop/env/lib/python3.10/site-packages/google/auth/transport/requests.py", line 541, in request
    response = super(AuthorizedSession, self).request(
  File "/home/sam/Desktop/control_loop/env/lib/python3.10/site-packages/requests/sessions.py", line 589, in request
    resp = self.send(prep, **send_kwargs)
  File "/home/sam/Desktop/control_loop/env/lib/python3.10/site-packages/requests/sessions.py", line 703, in send
    r = adapter.send(request, **kwargs)
  File "/home/sam/Desktop/control_loop/env/lib/python3.10/site-packages/requests/adapters.py", line 604, in send
    raise ConnectionError(err, request=request)
requests.exceptions.ConnectionError: ('Connection aborted.', RemoteDisconnected('Remote end closed connection without response'))

2024-07-05 09:26:56 - ERROR - Backup Server Started
